Workbook

Sheet Start here
B2: paid in yellow · Paycheck Payoff Planner
B3: Your debt-free date, and a clear amount to move every payday. One paycheck at a time.
B5: How it works
B6: 1. Setup: how often you're paid, your next payday, and how much you can put toward the plan each payday.
B7: 2. Debts: one row per debt (up to 50): balance, interest rate, monthly minimum and due day. The due day is on your statement.
B8: 3. This payday: the exact amounts to move this payday, debt by debt. Pay them, then type Paid on that row of the Plan tab.
B9: 4. Progress: your debt-free date, what you've paid off, and the interest you avoid compared with paying only minimums.
B11: The cells to fill in
B12: White cells with a dark border are yours to type in. Everything else does the math. The example numbers are there to show the format: replace them with yours.
B14: How the plan pays
B15: Every debt gets its full monthly minimum on the payday before its due date. Your money for the plan fills your yearly bills, then your buffer, then goes to one debt at a time.
B16: When a debt is gone, its minimum keeps going: it joins the extra for the next debt. Balances only move by what you actually pay, plus interest.
... B31: one paycheck at a time

Sheet Setup
B2: Setup
B3: Fill in the white cells. You can change them any time.
B5: Currency symbol | C5: $ | E5: Any symbol: $, £, €, MAD...
B7: How often you're paid | C7: Every 2 weeks | E7: Every week · Every 2 weeks · Twice a month · Every month
B8: Your next payday | C8: 46325 | E8: The plan starts on this payday.
B9: Twice a month only: your other pay day | E9: For example 15, or 31 for the last day. Leave empty to use the usual pairing.
B11: Money for the plan each payday (on top of minimums) | C11: 100 | E11: Even 20 matters. You can change it any time.
B13: Buffer: set aside now | C13: 300 | E13: Money for surprises. Empty is fine.
B14: Buffer goal | C14: 500 | E14: A plain separate account or an envelope.
B16: Payoff order | C16: PaidInYellow order | E16: PaidInYellow order (smallest first, growing debts first) · Biggest interest first · My own order
B18: Yearly bills (optional)
B19: Bills that come once a year, saved a little each payday.
B20: Bill | C20: Per year | D20: Month needed
B21: Gifts and holidays | C21: 240 | D21: December
B32: Total per year | C32: =SUM(C21:C30) -> 240
B35: Worked out for you
B36: Paydays per year | C36: =IF(C7="Every week",52,IF(C7="Every 2 weeks",26,IF(C7="Twice a month",24,12))) -> 26
B37: Yearly bills per payday | C37: =C32/C36 -> 9.2307692
B38: Other pay day used | C38: =IF(C9>0,C9,IF(DAY(C8)<=15,DAY(C8)+15,IF(DAY(C8)=DAY(EOMONTH(C8,0)),15,DAY(C8)-15))) -> 15
B39: First pay day of the month | C39: =MIN(DAY(C8),C38) -> 15
B40: Second pay day of the month | C40: =MAX(DAY(C8),C38) -> 30
B41: Plan starts on the second one | C41: =IF(DAY(C8)=C39,0,1) -> 1

Sheet Debts
B2: Debts
B3: One row per debt. Balance, rate and minimum are on your statement. Due day is the day of the month it's due.
A5: # | B5: Name | C5: Type | D5: Balance | E5: Rate % | F5: Monthly minimum | G5: Due day | H5: My order | I5: Grows? | J5: Sort key | K5: Order | L5: Gone by | M5: Status | N5: Minimums only: months | O5: Minimums only: interest
A6: 1 | B6: Card A | C6: Credit card | D6: 500 | E6: 24 | F6: 25 | G6: 10 | I6: =IF(AND(D6>0,E6>0,F6<=D6*E6/1200),"Grows","") | J6: =IF(N(D6)<=0,5000000000000000,IF(Setup!$C$16="Biggest interest first",ROUND((100-E6)*1000,0)*10000000000+ROUND(D6*100,0),IF(Setup!$C$16="My own order",IF(H6>0,H6,999),IF(I6="Grows",ROUND((100-E6)*1000,0),1000000+ROUND(D6*100,0))))) -> 1050000 | K6: =COUNTIF($J$6:$J$55,"<"&J6)+COUNTIFS($J$6:$J$55,J6,$A$6:$A$55,"<"&A6)+1 -> 1 | L6: =IF(N(D6)<=0,"",IFERROR(INDEX(Plan!$B$9:$B$528,COUNTIF(INDEX(BalBlock,0,K6),">0.005")+1),"More than 20 years")) -> 46423 | M6: =IF(N(D6)<=0,"",IF(INDEX(BalNow,1,K6)<0.005,"PAID","")) | N6: =IF(N(D6)<=0,"",IF(N(F6)<=0,"Never ends",IF(AND(E6>0,F6<=D6*E6/1200),"Never ends",IF(N(E6)=0,D6/F6,NPER(E6/1200,-F6,D6))))) -> 25.795851 | O6: =IF(ISNUMBER(N6),F6*N6-D6,"") -> 144.89628
A7: 2 | B7: Card B | C7: Credit card | D7: 1200 | E7: 18 | F7: 40 | G7: 20 | I7: =IF(AND(D7>0,E7>0,F7<=D7*E7/1200),"Grows","") | J7: =IF(N(D7)<=0,5000000000000000,IF(Setup!$C$16="Biggest interest first",ROUND((100-E7)*1000,0)*10000000000+ROUND(D7*100,0),IF(Setup!$C$16="My own order",IF(H7>0,H7,999),IF(I7="Grows",ROUND((100-E7)*1000,0),1000000+ROUND(D7*100,0))))) -> 1120000 | K7: =COUNTIF($J$6:$J$55,"<"&J7)+COUNTIFS($J$6:$J$55,J7,$A$6:$A$55,"<"&A7)+1 -> 2 | L7: =IF(N(D7)<=0,"",IFERROR(INDEX(Plan!$B$9:$B$528,COUNTIF(INDEX(BalBlock,0,K7),">0.005")+1),"More than 20 years")) -> 46549 | M7: =IF(N(D7)<=0,"",IF(INDEX(BalNow,1,K7)<0.005,"PAID","")) | N7: =IF(N(D7)<=0,"",IF(N(F7)<=0,"Never ends",IF(AND(E7>0,F7<=D7*E7/1200),"Never ends",IF(N(E7)=0,D7/F7,NPER(E7/1200,-F7,D7))))) -> 40.153977 | O7: =IF(ISNUMBER(N7),F7*N7-D7,"") -> 406.15907
A8: 3 | I8: =IF(AND(D8>0,E8>0,F8<=D8*E8/1200),"Grows","") | J8: =IF(N(D8)<=0,5000000000000000,IF(Setup!$C$16="Biggest interest first",ROUND((100-E8)*1000,0)*10000000000+ROUND(D8*100,0),IF(Setup!$C$16="My own order",IF(H8>0,H8,999),IF(I8="Grows",ROUND((100-E8)*1000,0),1000000+ROUND(D8*100,0))))) -> 5e+15 | K8: =COUNTIF($J$6:$J$55,"<"&J8)+COUNTIFS($J$6:$J$55,J8,$A$6:$A$55,"<"&A8)+1 -> 3 | L8: =IF(N(D8)<=0,"",IFERROR(INDEX(Plan!$B$9:$B$528,COUNTIF(INDEX(BalBlock,0,K8),">0.005")+1),"More than 20 years")) | M8: =IF(N(D8)<=0,"",IF(INDEX(BalNow,1,K8)<0.005,"PAID","")) | N8: =IF(N(D8)<=0,"",IF(N(F8)<=0,"Never ends",IF(AND(E8>0,F8<=D8*E8/1200),"Never ends",IF(N(E8)=0,D8/F8,NPER(E8/1200,-F8,D8))))) | O8: =IF(ISNUMBER(N8),F8*N8-D8,"")
A9: 4 | I9: =IF(AND(D9>0,E9>0,F9<=D9*E9/1200),"Grows","") | J9: =IF(N(D9)<=0,5000000000000000,IF(Setup!$C$16="Biggest interest first",ROUND((100-E9)*1000,0)*10000000000+ROUND(D9*100,0),IF(Setup!$C$16="My own order",IF(H9>0,H9,999),IF(I9="Grows",ROUND((100-E9)*1000,0),1000000+ROUND(D9*100,0))))) -> 5e+15 | K9: =COUNTIF($J$6:$J$55,"<"&J9)+COUNTIFS($J$6:$J$55,J9,$A$6:$A$55,"<"&A9)+1 -> 4 | L9: =IF(N(D9)<=0,"",IFERROR(INDEX(Plan!$B$9:$B$528,COUNTIF(INDEX(BalBlock,0,K9),">0.005")+1),"More than 20 years")) | M9: =IF(N(D9)<=0,"",IF(INDEX(BalNow,1,K9)<0.005,"PAID","")) | N9: =IF(N(D9)<=0,"",IF(N(F9)<=0,"Never ends",IF(AND(E9>0,F9<=D9*E9/1200),"Never ends",IF(N(E9)=0,D9/F9,NPER(E9/1200,-F9,D9))))) | O9: =IF(ISNUMBER(N9),F9*N9-D9,"")
A10: 5 | I10: =IF(AND(D10>0,E10>0,F10<=D10*E10/1200),"Grows","") | J10: =IF(N(D10)<=0,5000000000000000,IF(Setup!$C$16="Biggest interest first",ROUND((100-E10)*1000,0)*10000000000+ROUND(D10*100,0),IF(Setup!$C$16="My own order",IF(H10>0,H10,999),IF(I10="Grows",ROUND((100-E10)*1000,0),1000000+ROUND(D10*100,0))))) -> 5e+15 | K10: =COUNTIF($J$6:$J$55,"<"&J10)+COUNTIFS($J$6:$J$55,J10,$A$6:$A$55,"<"&A10)+1 -> 5 | L10: =IF(N(D10)<=0,"",IFERROR(INDEX(Plan!$B$9:$B$528,COUNTIF(INDEX(BalBlock,0,K10),">0.005")+1),"More than 20 years")) | M10: =IF(N(D10)<=0,"",IF(INDEX(BalNow,1,K10)<0.005,"PAID","")) | N10: =IF(N(D10)<=0,"",IF(N(F10)<=0,"Never ends",IF(AND(E10>0,F10<=D10*E10/1200),"Never ends",IF(N(E10)=0,D10/F10,NPER(E10/1200,-F10,D10))))) | O10: =IF(ISNUMBER(N10),F10*N10-D10,"")
A11: 6 | I11: =IF(AND(D11>0,E11>0,F11<=D11*E11/1200),"Grows","") | J11: =IF(N(D11)<=0,5000000000000000,IF(Setup!$C$16="Biggest interest first",ROUND((100-E11)*1000,0)*10000000000+ROUND(D11*100,0),IF(Setup!$C$16="My own order",IF(H11>0,H11,999),IF(I11="Grows",ROUND((100-E11)*1000,0),1000000+ROUND(D11*100,0))))) -> 5e+15 | K11: =COUNTIF($J$6:$J$55,"<"&J11)+COUNTIFS($J$6:$J$55,J11,$A$6:$A$55,"<"&A11)+1 -> 6 | L11: =IF(N(D11)<=0,"",IFERROR(INDEX(Plan!$B$9:$B$528,COUNTIF(INDEX(BalBlock,0,K11),">0.005")+1),"More than 20 years")) | M11: =IF(N(D11)<=0,"",IF(INDEX(BalNow,1,K11)<0.005,"PAID","")) | N11: =IF(N(D11)<=0,"",IF(N(F11)<=0,"Never ends",IF(AND(E11>0,F11<=D11*E11/1200),"Never ends",IF(N(E11)=0,D11/F11,NPER(E11/1200,-F11,D11))))) | O11: =IF(ISNUMBER(N11),F11*N11-D11,"")
A12: 7 | I12: =IF(AND(D12>0,E12>0,F12<=D12*E12/1200),"Grows","") | J12: =IF(N(D12)<=0,5000000000000000,IF(Setup!$C$16="Biggest interest first",ROUND((100-E12)*1000,0)*10000000000+ROUND(D12*100,0),IF(Setup!$C$16="My own order",IF(H12>0,H12,999),IF(I12="Grows",ROUND((100-E12)*1000,0),1000000+ROUND(D12*100,0))))) -> 5e+15 | K12: =COUNTIF($J$6:$J$55,"<"&J12)+COUNTIFS($J$6:$J$55,J12,$A$6:$A$55,"<"&A12)+1 -> 7 | L12: =IF(N(D12)<=0,"",IFERROR(INDEX(Plan!$B$9:$B$528,COUNTIF(INDEX(BalBlock,0,K12),">0.005")+1),"More than 20 years")) | M12: =IF(N(D12)<=0,"",IF(INDEX(BalNow,1,K12)<0.005,"PAID","")) | N12: =IF(N(D12)<=0,"",IF(N(F12)<=0,"Never ends",IF(AND(E12>0,F12<=D12*E12/1200),"Never ends",IF(N(E12)=0,D12/F12,NPER(E12/1200,-F12,D12))))) | O12: =IF(ISNUMBER(N12),F12*N12-D12,"")
A13: 8 | I13: =IF(AND(D13>0,E13>0,F13<=D13*E13/1200),"Grows","") | J13: =IF(N(D13)<=0,5000000000000000,IF(Setup!$C$16="Biggest interest first",ROUND((100-E13)*1000,0)*10000000000+ROUND(D13*100,0),IF(Setup!$C$16="My own order",IF(H13>0,H13,999),IF(I13="Grows",ROUND((100-E13)*1000,0),1000000+ROUND(D13*100,0))))) -> 5e+15 | K13: =COUNTIF($J$6:$J$55,"<"&J13)+COUNTIFS($J$6:$J$55,J13,$A$6:$A$55,"<"&A13)+1 -> 8 | L13: =IF(N(D13)<=0,"",IFERROR(INDEX(Plan!$B$9:$B$528,COUNTIF(INDEX(BalBlock,0,K13),">0.005")+1),"More than 20 years")) | M13: =IF(N(D13)<=0,"",IF(INDEX(BalNow,1,K13)<0.005,"PAID","")) | N13: =IF(N(D13)<=0,"",IF(N(F13)<=0,"Never ends",IF(AND(E13>0,F13<=D13*E13/1200),"Never ends",IF(N(E13)=0,D13/F13,NPER(E13/1200,-F13,D13))))) | O13: =IF(ISNUMBER(N13),F13*N13-D13,"")
A14: 9 | I14: =IF(AND(D14>0,E14>0,F14<=D14*E14/1200),"Grows","") | J14: =IF(N(D14)<=0,5000000000000000,IF(Setup!$C$16="Biggest interest first",ROUND((100-E14)*1000,0)*10000000000+ROUND(D14*100,0),IF(Setup!$C$16="My own order",IF(H14>0,H14,999),IF(I14="Grows",ROUND((100-E14)*1000,0),1000000+ROUND(D14*100,0))))) -> 5e+15 | K14: =COUNTIF($J$6:$J$55,"<"&J14)+COUNTIFS($J$6:$J$55,J14,$A$6:$A$55,"<"&A14)+1 -> 9 | L14: =IF(N(D14)<=0,"",IFERROR(INDEX(Plan!$B$9:$B$528,COUNTIF(INDEX(BalBlock,0,K14),">0.005")+1),"More than 20 years")) | M14: =IF(N(D14)<=0,"",IF(INDEX(BalNow,1,K14)<0.005,"PAID","")) | N14: =IF(N(D14)<=0,"",IF(N(F14)<=0,"Never ends",IF(AND(E14>0,F14<=D14*E14/1200),"Never ends",IF(N(E14)=0,D14/F14,NPER(E14/1200,-F14,D14))))) | O14: =IF(ISNUMBER(N14),F14*N14-D14,"")
A15: 10 | I15: =IF(AND(D15>0,E15>0,F15<=D15*E15/1200),"Grows","") | J15: =IF(N(D15)<=0,5000000000000000,IF(Setup!$C$16="Biggest interest first",ROUND((100-E15)*1000,0)*10000000000+ROUND(D15*100,0),IF(Setup!$C$16="My own order",IF(H15>0,H15,999),IF(I15="Grows",ROUND((100-E15)*1000,0),1000000+ROUND(D15*100,0))))) -> 5e+15 | K15: =COUNTIF($J$6:$J$55,"<"&J15)+COUNTIFS($J$6:$J$55,J15,$A$6:$A$55,"<"&A15)+1 -> 10 | L15: =IF(N(D15)<=0,"",IFERROR(INDEX(Plan!$B$9:$B$528,COUNTIF(INDEX(BalBlock,0,K15),">0.005")+1),"More than 20 years")) | M15: =IF(N(D15)<=0,"",IF(INDEX(BalNow,1,K15)<0.005,"PAID","")) | N15: =IF(N(D15)<=0,"",IF(N(F15)<=0,"Never ends",IF(AND(E15>0,F15<=D15*E15/1200),"Never ends",IF(N(E15)=0,D15/F15,NPER(E15/1200,-F15,D15))))) | O15: =IF(ISNUMBER(N15),F15*N15-D15,"")
A16: 11 | I16: =IF(AND(D16>0,E16>0,F16<=D16*E16/1200),"Grows","") | J16: =IF(N(D16)<=0,5000000000000000,IF(Setup!$C$16="Biggest interest first",ROUND((100-E16)*1000,0)*10000000000+ROUND(D16*100,0),IF(Setup!$C$16="My own order",IF(H16>0,H16,999),IF(I16="Grows",ROUND((100-E16)*1000,0),1000000+ROUND(D16*100,0))))) -> 5e+15 | K16: =COUNTIF($J$6:$J$55,"<"&J16)+COUNTIFS($J$6:$J$55,J16,$A$6:$A$55,"<"&A16)+1 -> 11 | L16: =IF(N(D16)<=0,"",IFERROR(INDEX(Plan!$B$9:$B$528,COUNTIF(INDEX(BalBlock,0,K16),">0.005")+1),"More than 20 years")) | M16: =IF(N(D16)<=0,"",IF(INDEX(BalNow,1,K16)<0.005,"PAID","")) | N16: =IF(N(D16)<=0,"",IF(N(F16)<=0,"Never ends",IF(AND(E16>0,F16<=D16*E16/1200),"Never ends",IF(N(E16)=0,D16/F16,NPER(E16/1200,-F16,D16))))) | O16: =IF(ISNUMBER(N16),F16*N16-D16,"")
A17: 12 | I17: =IF(AND(D17>0,E17>0,F17<=D17*E17/1200),"Grows","") | J17: =IF(N(D17)<=0,5000000000000000,IF(Setup!$C$16="Biggest interest first",ROUND((100-E17)*1000,0)*10000000000+ROUND(D17*100,0),IF(Setup!$C$16="My own order",IF(H17>0,H17,999),IF(I17="Grows",ROUND((100-E17)*1000,0),1000000+ROUND(D17*100,0))))) -> 5e+15 | K17: =COUNTIF($J$6:$J$55,"<"&J17)+COUNTIFS($J$6:$J$55,J17,$A$6:$A$55,"<"&A17)+1 -> 12 | L17: =IF(N(D17)<=0,"",IFERROR(INDEX(Plan!$B$9:$B$528,COUNTIF(INDEX(BalBlock,0,K17),">0.005")+1),"More than 20 years")) | M17: =IF(N(D17)<=0,"",IF(INDEX(BalNow,1,K17)<0.005,"PAID","")) | N17: =IF(N(D17)<=0,"",IF(N(F17)<=0,"Never ends",IF(AND(E17>0,F17<=D17*E17/1200),"Never ends",IF(N(E17)=0,D17/F17,NPER(E17/1200,-F17,D17))))) | O17: =IF(ISNUMBER(N17),F17*N17-D17,"")
A18: 13 | I18: =IF(AND(D18>0,E18>0,F18<=D18*E18/1200),"Grows","") | J18: =IF(N(D18)<=0,5000000000000000,IF(Setup!$C$16="Biggest interest first",ROUND((100-E18)*1000,0)*10000000000+ROUND(D18*100,0),IF(Setup!$C$16="My own order",IF(H18>0,H18,999),IF(I18="Grows",ROUND((100-E18)*1000,0),1000000+ROUND(D18*100,0))))) -> 5e+15 | K18: =COUNTIF($J$6:$J$55,"<"&J18)+COUNTIFS($J$6:$J$55,J18,$A$6:$A$55,"<"&A18)+1 -> 13 | L18: =IF(N(D18)<=0,"",IFERROR(INDEX(Plan!$B$9:$B$528,COUNTIF(INDEX(BalBlock,0,K18),">0.005")+1),"More than 20 years")) | M18: =IF(N(D18)<=0,"",IF(INDEX(BalNow,1,K18)<0.005,"PAID","")) | N18: =IF(N(D18)<=0,"",IF(N(F18)<=0,"Never ends",IF(AND(E18>0,F18<=D18*E18/1200),"Never ends",IF(N(E18)=0,D18/F18,NPER(E18/1200,-F18,D18))))) | O18: =IF(ISNUMBER(N18),F18*N18-D18,"")
A19: 14 | I19: =IF(AND(D19>0,E19>0,F19<=D19*E19/1200),"Grows","") | J19: =IF(N(D19)<=0,5000000000000000,IF(Setup!$C$16="Biggest interest first",ROUND((100-E19)*1000,0)*10000000000+ROUND(D19*100,0),IF(Setup!$C$16="My own order",IF(H19>0,H19,999),IF(I19="Grows",ROUND((100-E19)*1000,0),1000000+ROUND(D19*100,0))))) -> 5e+15 | K19: =COUNTIF($J$6:$J$55,"<"&J19)+COUNTIFS($J$6:$J$55,J19,$A$6:$A$55,"<"&A19)+1 -> 14 | L19: =IF(N(D19)<=0,"",IFERROR(INDEX(Plan!$B$9:$B$528,COUNTIF(INDEX(BalBlock,0,K19),">0.005")+1),"More than 20 years")) | M19: =IF(N(D19)<=0,"",IF(INDEX(BalNow,1,K19)<0.005,"PAID","")) | N19: =IF(N(D19)<=0,"",IF(N(F19)<=0,"Never ends",IF(AND(E19>0,F19<=D19*E19/1200),"Never ends",IF(N(E19)=0,D19/F19,NPER(E19/1200,-F19,D19))))) | O19: =IF(ISNUMBER(N19),F19*N19-D19,"")
... A55: 50 | I55: =IF(AND(D55>0,E55>0,F55<=D55*E55/1200),"Grows","") | J55: =IF(N(D55)<=0,5000000000000000,IF(Setup!$C$16="Biggest interest first",ROUND((100-E55)*1000,0)*10000000000+ROUND(D55*100,0),IF(Setup!$C$16="My own order",IF(H55>0,H55,999),IF(I55="Grows",ROUND((100-E55)*1000,0),1000000+ROUND(D55*100,0))))) -> 5e+15 | K55: =COUNTIF($J$6:$J$55,"<"&J55)+COUNTIFS($J$6:$J$55,J55,$A$6:$A$55,"<"&A55)+1 -> 50 | L55: =IF(N(D55)<=0,"",IFERROR(INDEX(Plan!$B$9:$B$528,COUNTIF(INDEX(BalBlock,0,K55),">0.005")+1),"More than 20 years")) | M55: =IF(N(D55)<=0,"",IF(INDEX(BalNow,1,K55)<0.005,"PAID","")) | N55: =IF(N(D55)<=0,"",IF(N(F55)<=0,"Never ends",IF(AND(E55>0,F55<=D55*E55/1200),"Never ends",IF(N(E55)=0,D55/F55,NPER(E55/1200,-F55,D55))))) | O55: =IF(ISNUMBER(N55),F55*N55-D55,"")
B57: Total | D57: =SUM(D6:D55) -> 1700 | F57: =SUM(F6:F55) -> 65

Sheet This payday
H1: row | I1: =IFERROR(MATCH(1,Plan!$W$9:$W$528,0),0) -> 1
B2: This payday | I2: =IF(I1=0,0,INDEX(Plan!$A$9:$A$528,I1)) -> 1
B3: =IF($I$1=0,IF(Plan!$T$528<0.005,"You're debt-free. Keep your buffer and yearly bills going.","All planned paydays are marked Paid."),"Payday "&TEXT(INDEX(Plan!$B$9:$B$528,$I$1),"ddd d mmm yyyy")) -> Payday Fri 30 Oct 2026
B5: MOVE
B6: =IF($I$1=0,"",Setup!$C$5&TEXT(INDEX(Plan!$R$9:$R$528,$I$1),"#,##0")) -> $125
B8: =IF($I$1=0,"",IF(INDEX(Plan!$Q$9:$Q$528,$I$1)>0.005,"The extra "&Setup!$C$5&TEXT(INDEX(Plan!$Q$9:$Q$528,$I$1),"#,##0")&" goes to "&INDEX(Plan!$U$9:$U$528,$I$1)&".",IF(INDEX(Plan!$K$9:$K$528,$I$1)>0.005,"Your buffer fills first. Extra for your debts starts once it reaches "&Setup!$C$5&TEXT(Setup!$C$14,"#,##0")&".",""))) -> Your buffer fills first. Extra for your debts starts once it reaches $500.
B10: What | C10: Bill | D10: Extra | E10: Due | F10: Total
B11: =IFERROR(INDEX(Helpers!$C$2:$C$51,MATCH(1,$C$64:$AZ$64,0)),"") -> Card A | C11: =IFERROR(INDEX($C$61:$AZ$61,MATCH(1,$C$64:$AZ$64,0)),"") -> 25 | D11: =IFERROR(INDEX($C$62:$AZ$62,MATCH(1,$C$64:$AZ$64,0)),"") -> 0 | E11: =IFERROR(INDEX($C$65:$AZ$65,MATCH(1,$C$64:$AZ$64,0)),"") -> 46336 | F11: =IF(B11="","",N(C11)+N(D11)) -> 25
B12: =IFERROR(INDEX(Helpers!$C$2:$C$51,MATCH(2,$C$64:$AZ$64,0)),"") | C12: =IFERROR(INDEX($C$61:$AZ$61,MATCH(2,$C$64:$AZ$64,0)),"") | D12: =IFERROR(INDEX($C$62:$AZ$62,MATCH(2,$C$64:$AZ$64,0)),"") | E12: =IFERROR(INDEX($C$65:$AZ$65,MATCH(2,$C$64:$AZ$64,0)),"") | F12: =IF(B12="","",N(C12)+N(D12))
B13: =IFERROR(INDEX(Helpers!$C$2:$C$51,MATCH(3,$C$64:$AZ$64,0)),"") | C13: =IFERROR(INDEX($C$61:$AZ$61,MATCH(3,$C$64:$AZ$64,0)),"") | D13: =IFERROR(INDEX($C$62:$AZ$62,MATCH(3,$C$64:$AZ$64,0)),"") | E13: =IFERROR(INDEX($C$65:$AZ$65,MATCH(3,$C$64:$AZ$64,0)),"") | F13: =IF(B13="","",N(C13)+N(D13))
B14: =IFERROR(INDEX(Helpers!$C$2:$C$51,MATCH(4,$C$64:$AZ$64,0)),"") | C14: =IFERROR(INDEX($C$61:$AZ$61,MATCH(4,$C$64:$AZ$64,0)),"") | D14: =IFERROR(INDEX($C$62:$AZ$62,MATCH(4,$C$64:$AZ$64,0)),"") | E14: =IFERROR(INDEX($C$65:$AZ$65,MATCH(4,$C$64:$AZ$64,0)),"") | F14: =IF(B14="","",N(C14)+N(D14))
B15: =IFERROR(INDEX(Helpers!$C$2:$C$51,MATCH(5,$C$64:$AZ$64,0)),"") | C15: =IFERROR(INDEX($C$61:$AZ$61,MATCH(5,$C$64:$AZ$64,0)),"") | D15: =IFERROR(INDEX($C$62:$AZ$62,MATCH(5,$C$64:$AZ$64,0)),"") | E15: =IFERROR(INDEX($C$65:$AZ$65,MATCH(5,$C$64:$AZ$64,0)),"") | F15: =IF(B15="","",N(C15)+N(D15))
B16: =IFERROR(INDEX(Helpers!$C$2:$C$51,MATCH(6,$C$64:$AZ$64,0)),"") | C16: =IFERROR(INDEX($C$61:$AZ$61,MATCH(6,$C$64:$AZ$64,0)),"") | D16: =IFERROR(INDEX($C$62:$AZ$62,MATCH(6,$C$64:$AZ$64,0)),"") | E16: =IFERROR(INDEX($C$65:$AZ$65,MATCH(6,$C$64:$AZ$64,0)),"") | F16: =IF(B16="","",N(C16)+N(D16))
B17: =IFERROR(INDEX(Helpers!$C$2:$C$51,MATCH(7,$C$64:$AZ$64,0)),"") | C17: =IFERROR(INDEX($C$61:$AZ$61,MATCH(7,$C$64:$AZ$64,0)),"") | D17: =IFERROR(INDEX($C$62:$AZ$62,MATCH(7,$C$64:$AZ$64,0)),"") | E17: =IFERROR(INDEX($C$65:$AZ$65,MATCH(7,$C$64:$AZ$64,0)),"") | F17: =IF(B17="","",N(C17)+N(D17))
B18: =IFERROR(INDEX(Helpers!$C$2:$C$51,MATCH(8,$C$64:$AZ$64,0)),"") | C18: =IFERROR(INDEX($C$61:$AZ$61,MATCH(8,$C$64:$AZ$64,0)),"") | D18: =IFERROR(INDEX($C$62:$AZ$62,MATCH(8,$C$64:$AZ$64,0)),"") | E18: =IFERROR(INDEX($C$65:$AZ$65,MATCH(8,$C$64:$AZ$64,0)),"") | F18: =IF(B18="","",N(C18)+N(D18))
B19: =IFERROR(INDEX(Helpers!$C$2:$C$51,MATCH(9,$C$64:$AZ$64,0)),"") | C19: =IFERROR(INDEX($C$61:$AZ$61,MATCH(9,$C$64:$AZ$64,0)),"") | D19: =IFERROR(INDEX($C$62:$AZ$62,MATCH(9,$C$64:$AZ$64,0)),"") | E19: =IFERROR(INDEX($C$65:$AZ$65,MATCH(9,$C$64:$AZ$64,0)),"") | F19: =IF(B19="","",N(C19)+N(D19))
B20: =IFERROR(INDEX(Helpers!$C$2:$C$51,MATCH(10,$C$64:$AZ$64,0)),"") | C20: =IFERROR(INDEX($C$61:$AZ$61,MATCH(10,$C$64:$AZ$64,0)),"") | D20: =IFERROR(INDEX($C$62:$AZ$62,MATCH(10,$C$64:$AZ$64,0)),"") | E20: =IFERROR(INDEX($C$65:$AZ$65,MATCH(10,$C$64:$AZ$64,0)),"") | F20: =IF(B20="","",N(C20)+N(D20))
B21: =IFERROR(INDEX(Helpers!$C$2:$C$51,MATCH(11,$C$64:$AZ$64,0)),"") | C21: =IFERROR(INDEX($C$61:$AZ$61,MATCH(11,$C$64:$AZ$64,0)),"") | D21: =IFERROR(INDEX($C$62:$AZ$62,MATCH(11,$C$64:$AZ$64,0)),"") | E21: =IFERROR(INDEX($C$65:$AZ$65,MATCH(11,$C$64:$AZ$64,0)),"") | F21: =IF(B21="","",N(C21)+N(D21))
B22: =IFERROR(INDEX(Helpers!$C$2:$C$51,MATCH(12,$C$64:$AZ$64,0)),"") | C22: =IFERROR(INDEX($C$61:$AZ$61,MATCH(12,$C$64:$AZ$64,0)),"") | D22: =IFERROR(INDEX($C$62:$AZ$62,MATCH(12,$C$64:$AZ$64,0)),"") | E22: =IFERROR(INDEX($C$65:$AZ$65,MATCH(12,$C$64:$AZ$64,0)),"") | F22: =IF(B22="","",N(C22)+N(D22))
B23: =IFERROR(INDEX(Helpers!$C$2:$C$51,MATCH(13,$C$64:$AZ$64,0)),"") | C23: =IFERROR(INDEX($C$61:$AZ$61,MATCH(13,$C$64:$AZ$64,0)),"") | D23: =IFERROR(INDEX($C$62:$AZ$62,MATCH(13,$C$64:$AZ$64,0)),"") | E23: =IFERROR(INDEX($C$65:$AZ$65,MATCH(13,$C$64:$AZ$64,0)),"") | F23: =IF(B23="","",N(C23)+N(D23))
B24: =IFERROR(INDEX(Helpers!$C$2:$C$51,MATCH(14,$C$64:$AZ$64,0)),"") | C24: =IFERROR(INDEX($C$61:$AZ$61,MATCH(14,$C$64:$AZ$64,0)),"") | D24: =IFERROR(INDEX($C$62:$AZ$62,MATCH(14,$C$64:$AZ$64,0)),"") | E24: =IFERROR(INDEX($C$65:$AZ$65,MATCH(14,$C$64:$AZ$64,0)),"") | F24: =IF(B24="","",N(C24)+N(D24))
B25: =IFERROR(INDEX(Helpers!$C$2:$C$51,MATCH(15,$C$64:$AZ$64,0)),"") | C25: =IFERROR(INDEX($C$61:$AZ$61,MATCH(15,$C$64:$AZ$64,0)),"") | D25: =IFERROR(INDEX($C$62:$AZ$62,MATCH(15,$C$64:$AZ$64,0)),"") | E25: =IFERROR(INDEX($C$65:$AZ$65,MATCH(15,$C$64:$AZ$64,0)),"") | F25: =IF(B25="","",N(C25)+N(D25))
B26: =IFERROR(INDEX(Helpers!$C$2:$C$51,MATCH(16,$C$64:$AZ$64,0)),"") | C26: =IFERROR(INDEX($C$61:$AZ$61,MATCH(16,$C$64:$AZ$64,0)),"") | D26: =IFERROR(INDEX($C$62:$AZ$62,MATCH(16,$C$64:$AZ$64,0)),"") | E26: =IFERROR(INDEX($C$65:$AZ$65,MATCH(16,$C$64:$AZ$64,0)),"") | F26: =IF(B26="","",N(C26)+N(D26))
B27: Yearly bills pot | F27: =IF($I$1=0,"",INDEX(Plan!$J$9:$J$528,$I$1)) -> 9.2307692
B28: Buffer | F28: =IF($I$1=0,"",INDEX(Plan!$K$9:$K$528,$I$1)) -> 90.769231
B29: Total to move | F29: =IF($I$1=0,"",INDEX(Plan!$R$9:$R$528,$I$1)) -> 125
B31: =IF($I$1=0,"","When it's done, type Paid in column D of the Plan tab, on payday #"&$I$2&". The next payday then shows here.") -> When it's done, type Paid in column D of the Plan tab, on payday #1. The next payday then shows here.
B33: one paycheck at a time
B59: helpers
C60: =IF($I$1=0,INDEX(Plan!$FT$9:$FT$528,520),IF($I$1=1,Plan!FT$8,INDEX(Plan!$FT$9:$FT$528,$I$1-1))) -> 500 | D60: =IF($I$1=0,INDEX(Plan!$FU$9:$FU$528,520),IF($I$1=1,Plan!FU$8,INDEX(Plan!$FU$9:$FU$528,$I$1-1))) -> 1200 | E60: =IF($I$1=0,INDEX(Plan!$FV$9:$FV$528,520),IF($I$1=1,Plan!FV$8,INDEX(Plan!$FV$9:$FV$528,$I$1-1))) -> 0 | F60: =IF($I$1=0,INDEX(Plan!$FW$9:$FW$528,520),IF($I$1=1,Plan!FW$8,INDEX(Plan!$FW$9:$FW$528,$I$1-1))) -> 0 | G60: =IF($I$1=0,INDEX(Plan!$FX$9:$FX$528,520),IF($I$1=1,Plan!FX$8,INDEX(Plan!$FX$9:$FX$528,$I$1-1))) -> 0 | H60: =IF($I$1=0,INDEX(Plan!$FY$9:$FY$528,520),IF($I$1=1,Plan!FY$8,INDEX(Plan!$FY$9:$FY$528,$I$1-1))) -> 0 | I60: =IF($I$1=0,INDEX(Plan!$FZ$9:$FZ$528,520),IF($I$1=1,Plan!FZ$8,INDEX(Plan!$FZ$9:$FZ$528,$I$1-1))) -> 0 | J60: =IF($I$1=0,INDEX(Plan!$GA$9:$GA$528,520),IF($I$1=1,Plan!GA$8,INDEX(Plan!$GA$9:$GA$528,$I$1-1))) -> 0 | K60: =IF($I$1=0,INDEX(Plan!$GB$9:$GB$528,520),IF($I$1=1,Plan!GB$8,INDEX(Plan!$GB$9:$GB$528,$I$1-1))) -> 0 | L60: =IF($I$1=0,INDEX(Plan!$GC$9:$GC$528,520),IF($I$1=1,Plan!GC$8,INDEX(Plan!$GC$9:$GC$528,$I$1-1))) -> 0 | M60: =IF($I$1=0,INDEX(Plan!$GD$9:$GD$528,520),IF($I$1=1,Plan!GD$8,INDEX(Plan!$GD$9:$GD$528,$I$1-1))) -> 0 | N60: =IF($I$1=0,INDEX(Plan!$GE$9:$GE$528,520),IF($I$1=1,Plan!GE$8,INDEX(Plan!$GE$9:$GE$528,$I$1-1))) -> 0 | O60: =IF($I$1=0,INDEX(Plan!$GF$9:$GF$528,520),IF($I$1=1,Plan!GF$8,INDEX(Plan!$GF$9:$GF$528,$I$1-1))) -> 0 | P60: =IF($I$1=0,INDEX(Plan!$GG$9:$GG$528,520),IF($I$1=1,Plan!GG$8,INDEX(Plan!$GG$9:$GG$528,$I$1-1))) -> 0 | Q60: =IF($I$1=0,INDEX(Plan!$GH$9:$GH$528,520),IF($I$1=1,Plan!GH$8,INDEX(Plan!$GH$9:$GH$528,$I$1-1))) -> 0 | R60: =IF($I$1=0,INDEX(Plan!$GI$9:$GI$528,520),IF($I$1=1,Plan!GI$8,INDEX(Plan!$GI$9:$GI$528,$I$1-1))) -> 0 | S60: =IF($I$1=0,INDEX(Plan!$GJ$9:$GJ$528,520),IF($I$1=1,Plan!GJ$8,INDEX(Plan!$GJ$9:$GJ$528,$I$1-1))) -> 0 | T60: =IF($I$1=0,INDEX(Plan!$GK$9:$GK$528,520),IF($I$1=1,Plan!GK$8,INDEX(Plan!$GK$9:$GK$528,$I$1-1))) -> 0 | U60: =IF($I$1=0,INDEX(Plan!$GL$9:$GL$528,520),IF($I$1=1,Plan!GL$8,INDEX(Plan!$GL$9:$GL$528,$I$1-1))) -> 0 | V60: =IF($I$1=0,INDEX(Plan!$GM$9:$GM$528,520),IF($I$1=1,Plan!GM$8,INDEX(Plan!$GM$9:$GM$528,$I$1-1))) -> 0 | W60: =IF($I$1=0,INDEX(Plan!$GN$9:$GN$528,520),IF($I$1=1,Plan!GN$8,INDEX(Plan!$GN$9:$GN$528,$I$1-1))) -> 0 | X60: =IF($I$1=0,INDEX(Plan!$GO$9:$GO$528,520),IF($I$1=1,Plan!GO$8,INDEX(Plan!$GO$9:$GO$528,$I$1-1))) -> 0 | Y60: =IF($I$1=0,INDEX(Plan!$GP$9:$GP$528,520),IF($I$1=1,Plan!GP$8,INDEX(Plan!$GP$9:$GP$528,$I$1-1))) -> 0 | Z60: =IF($I$1=0,INDEX(Plan!$GQ$9:$GQ$528,520),IF($I$1=1,Plan!GQ$8,INDEX(Plan!$GQ$9:$GQ$528,$I$1-1))) -> 0 | AA60: =IF($I$1=0,INDEX(Plan!$GR$9:$GR$528,520),IF($I$1=1,Plan!GR$8,INDEX(Plan!$GR$9:$GR$528,$I$1-1))) -> 0 | AB60: =IF($I$1=0,INDEX(Plan!$GS$9:$GS$528,520),IF($I$1=1,Plan!GS$8,INDEX(Plan!$GS$9:$GS$528,$I$1-1))) -> 0 | AC60: =IF($I$1=0,INDEX(Plan!$GT$9:$GT$528,520),IF($I$1=1,Plan!GT$8,INDEX(Plan!$GT$9:$GT$528,$I$1-1))) -> 0 | AD60: =IF($I$1=0,INDEX(Plan!$GU$9:$GU$528,520),IF($I$1=1,Plan!GU$8,INDEX(Plan!$GU$9:$GU$528,$I$1-1))) -> 0 | AE60: =IF($I$1=0,INDEX(Plan!$GV$9:$GV$528,520),IF($I$1=1,Plan!GV$8,INDEX(Plan!$GV$9:$GV$528,$I$1-1))) -> 0 | AF60: =IF($I$1=0,INDEX(Plan!$GW$9:$GW$528,520),IF($I$1=1,Plan!GW$8,INDEX(Plan!$GW$9:$GW$528,$I$1-1))) -> 0 | AG60: =IF($I$1=0,INDEX(Plan!$GX$9:$GX$528,520),IF($I$1=1,Plan!GX$8,INDEX(Plan!$GX$9:$GX$528,$I$1-1))) -> 0 | AH60: =IF($I$1=0,INDEX(Plan!$GY$9:$GY$528,520),IF($I$1=1,Plan!GY$8,INDEX(Plan!$GY$9:$GY$528,$I$1-1))) -> 0 | AI60: =IF($I$1=0,INDEX(Plan!$GZ$9:$GZ$528,520),IF($I$1=1,Plan!GZ$8,INDEX(Plan!$GZ$9:$GZ$528,$I$1-1))) -> 0 | AJ60: =IF($I$1=0,INDEX(Plan!$HA$9:$HA$528,520),IF($I$1=1,Plan!HA$8,INDEX(Plan!$HA$9:$HA$528,$I$1-1))) -> 0 | AK60: =IF($I$1=0,INDEX(Plan!$HB$9:$HB$528,520),IF($I$1=1,Plan!HB$8,INDEX(Plan!$HB$9:$HB$528,$I$1-1))) -> 0 | AL60: =IF($I$1=0,INDEX(Plan!$HC$9:$HC$528,520),IF($I$1=1,Plan!HC$8,INDEX(Plan!$HC$9:$HC$528,$I$1-1))) -> 0 | AM60: =IF($I$1=0,INDEX(Plan!$HD$9:$HD$528,520),IF($I$1=1,Plan!HD$8,INDEX(Plan!$HD$9:$HD$528,$I$1-1))) -> 0 | AN60: =IF($I$1=0,INDEX(Plan!$HE$9:$HE$528,520),IF($I$1=1,Plan!HE$8,INDEX(Plan!$HE$9:$HE$528,$I$1-1))) -> 0 | AO60: =IF($I$1=0,INDEX(Plan!$HF$9:$HF$528,520),IF($I$1=1,Plan!HF$8,INDEX(Plan!$HF$9:$HF$528,$I$1-1))) -> 0 | AP60: =IF($I$1=0,INDEX(Plan!$HG$9:$HG$528,520),IF($I$1=1,Plan!HG$8,INDEX(Plan!$HG$9:$HG$528,$I$1-1))) -> 0 | AQ60: =IF($I$1=0,INDEX(Plan!$HH$9:$HH$528,520),IF($I$1=1,Plan!HH$8,INDEX(Plan!$HH$9:$HH$528,$I$1-1))) -> 0 | AR60: =IF($I$1=0,INDEX(Plan!$HI$9:$HI$528,520),IF($I$1=1,Plan!HI$8,INDEX(Plan!$HI$9:$HI$528,$I$1-1))) -> 0 | AS60: =IF($I$1=0,INDEX(Plan!$HJ$9:$HJ$528,520),IF($I$1=1,Plan!HJ$8,INDEX(Plan!$HJ$9:$HJ$528,$I$1-1))) -> 0 | AT60: =IF($I$1=0,INDEX(Plan!$HK$9:$HK$528,520),IF($I$1=1,Plan!HK$8,INDEX(Plan!$HK$9:$HK$528,$I$1-1))) -> 0 | AU60: =IF($I$1=0,INDEX(Plan!$HL$9:$HL$528,520),IF($I$1=1,Plan!HL$8,INDEX(Plan!$HL$9:$HL$528,$I$1-1))) -> 0 | AV60: =IF($I$1=0,INDEX(Plan!$HM$9:$HM$528,520),IF($I$1=1,Plan!HM$8,INDEX(Plan!$HM$9:$HM$528,$I$1-1))) -> 0 | AW60: =IF($I$1=0,INDEX(Plan!$HN$9:$HN$528,520),IF($I$1=1,Plan!HN$8,INDEX(Plan!$HN$9:$HN$528,$I$1-1))) -> 0 | AX60: =IF($I$1=0,INDEX(Plan!$HO$9:$HO$528,520),IF($I$1=1,Plan!HO$8,INDEX(Plan!$HO$9:$HO$528,$I$1-1))) -> 0 | AY60: =IF($I$1=0,INDEX(Plan!$HP$9:$HP$528,520),IF($I$1=1,Plan!HP$8,INDEX(Plan!$HP$9:$HP$528,$I$1-1))) -> 0 | AZ60: =IF($I$1=0,INDEX(Plan!$HQ$9:$HQ$528,520),IF($I$1=1,Plan!HQ$8,INDEX(Plan!$HQ$9:$HQ$528,$I$1-1))) -> 0
C61: =IF($I$1=0,0,INDEX(Plan!$BX$9:$BX$528,$I$1)) -> 25 | D61: =IF($I$1=0,0,INDEX(Plan!$BY$9:$BY$528,$I$1)) -> 0 | E61: =IF($I$1=0,0,INDEX(Plan!$BZ$9:$BZ$528,$I$1)) -> 0 | F61: =IF($I$1=0,0,INDEX(Plan!$CA$9:$CA$528,$I$1)) -> 0 | G61: =IF($I$1=0,0,INDEX(Plan!$CB$9:$CB$528,$I$1)) -> 0 | H61: =IF($I$1=0,0,INDEX(Plan!$CC$9:$CC$528,$I$1)) -> 0 | I61: =IF($I$1=0,0,INDEX(Plan!$CD$9:$CD$528,$I$1)) -> 0 | J61: =IF($I$1=0,0,INDEX(Plan!$CE$9:$CE$528,$I$1)) -> 0 | K61: =IF($I$1=0,0,INDEX(Plan!$CF$9:$CF$528,$I$1)) -> 0 | L61: =IF($I$1=0,0,INDEX(Plan!$CG$9:$CG$528,$I$1)) -> 0 | M61: =IF($I$1=0,0,INDEX(Plan!$CH$9:$CH$528,$I$1)) -> 0 | N61: =IF($I$1=0,0,INDEX(Plan!$CI$9:$CI$528,$I$1)) -> 0 | O61: =IF($I$1=0,0,INDEX(Plan!$CJ$9:$CJ$528,$I$1)) -> 0 | P61: =IF($I$1=0,0,INDEX(Plan!$CK$9:$CK$528,$I$1)) -> 0 | Q61: =IF($I$1=0,0,INDEX(Plan!$CL$9:$CL$528,$I$1)) -> 0 | R61: =IF($I$1=0,0,INDEX(Plan!$CM$9:$CM$528,$I$1)) -> 0 | S61: =IF($I$1=0,0,INDEX(Plan!$CN$9:$CN$528,$I$1)) -> 0 | T61: =IF($I$1=0,0,INDEX(Plan!$CO$9:$CO$528,$I$1)) -> 0 | U61: =IF($I$1=0,0,INDEX(Plan!$CP$9:$CP$528,$I$1)) -> 0 | V61: =IF($I$1=0,0,INDEX(Plan!$CQ$9:$CQ$528,$I$1)) -> 0 | W61: =IF($I$1=0,0,INDEX(Plan!$CR$9:$CR$528,$I$1)) -> 0 | X61: =IF($I$1=0,0,INDEX(Plan!$CS$9:$CS$528,$I$1)) -> 0 | Y61: =IF($I$1=0,0,INDEX(Plan!$CT$9:$CT$528,$I$1)) -> 0 | Z61: =IF($I$1=0,0,INDEX(Plan!$CU$9:$CU$528,$I$1)) -> 0 | AA61: =IF($I$1=0,0,INDEX(Plan!$CV$9:$CV$528,$I$1)) -> 0 | AB61: =IF($I$1=0,0,INDEX(Plan!$CW$9:$CW$528,$I$1)) -> 0 | AC61: =IF($I$1=0,0,INDEX(Plan!$CX$9:$CX$528,$I$1)) -> 0 | AD61: =IF($I$1=0,0,INDEX(Plan!$CY$9:$CY$528,$I$1)) -> 0 | AE61: =IF($I$1=0,0,INDEX(Plan!$CZ$9:$CZ$528,$I$1)) -> 0 | AF61: =IF($I$1=0,0,INDEX(Plan!$DA$9:$DA$528,$I$1)) -> 0 | AG61: =IF($I$1=0,0,INDEX(Plan!$DB$9:$DB$528,$I$1)) -> 0 | AH61: =IF($I$1=0,0,INDEX(Plan!$DC$9:$DC$528,$I$1)) -> 0 | AI61: =IF($I$1=0,0,INDEX(Plan!$DD$9:$DD$528,$I$1)) -> 0 | AJ61: =IF($I$1=0,0,INDEX(Plan!$DE$9:$DE$528,$I$1)) -> 0 | AK61: =IF($I$1=0,0,INDEX(Plan!$DF$9:$DF$528,$I$1)) -> 0 | AL61: =IF($I$1=0,0,INDEX(Plan!$DG$9:$DG$528,$I$1)) -> 0 | AM61: =IF($I$1=0,0,INDEX(Plan!$DH$9:$DH$528,$I$1)) -> 0 | AN61: =IF($I$1=0,0,INDEX(Plan!$DI$9:$DI$528,$I$1)) -> 0 | AO61: =IF($I$1=0,0,INDEX(Plan!$DJ$9:$DJ$528,$I$1)) -> 0 | AP61: =IF($I$1=0,0,INDEX(Plan!$DK$9:$DK$528,$I$1)) -> 0 | AQ61: =IF($I$1=0,0,INDEX(Plan!$DL$9:$DL$528,$I$1)) -> 0 | AR61: =IF($I$1=0,0,INDEX(Plan!$DM$9:$DM$528,$I$1)) -> 0 | AS61: =IF($I$1=0,0,INDEX(Plan!$DN$9:$DN$528,$I$1)) -> 0 | AT61: =IF($I$1=0,0,INDEX(Plan!$DO$9:$DO$528,$I$1)) -> 0 | AU61: =IF($I$1=0,0,INDEX(Plan!$DP$9:$DP$528,$I$1)) -> 0 | AV61: =IF($I$1=0,0,INDEX(Plan!$DQ$9:$DQ$528,$I$1)) -> 0 | AW61: =IF($I$1=0,0,INDEX(Plan!$DR$9:$DR$528,$I$1)) -> 0 | AX61: =IF($I$1=0,0,INDEX(Plan!$DS$9:$DS$528,$I$1)) -> 0 | AY61: =IF($I$1=0,0,INDEX(Plan!$DT$9:$DT$528,$I$1)) -> 0 | AZ61: =IF($I$1=0,0,INDEX(Plan!$DU$9:$DU$528,$I$1)) -> 0
C62: =IF($I$1=0,0,INDEX(Plan!$DV$9:$DV$528,$I$1)) -> 0 | D62: =IF($I$1=0,0,INDEX(Plan!$DW$9:$DW$528,$I$1)) -> 0 | E62: =IF($I$1=0,0,INDEX(Plan!$DX$9:$DX$528,$I$1)) -> 0 | F62: =IF($I$1=0,0,INDEX(Plan!$DY$9:$DY$528,$I$1)) -> 0 | G62: =IF($I$1=0,0,INDEX(Plan!$DZ$9:$DZ$528,$I$1)) -> 0 | H62: =IF($I$1=0,0,INDEX(Plan!$EA$9:$EA$528,$I$1)) -> 0 | I62: =IF($I$1=0,0,INDEX(Plan!$EB$9:$EB$528,$I$1)) -> 0 | J62: =IF($I$1=0,0,INDEX(Plan!$EC$9:$EC$528,$I$1)) -> 0 | K62: =IF($I$1=0,0,INDEX(Plan!$ED$9:$ED$528,$I$1)) -> 0 | L62: =IF($I$1=0,0,INDEX(Plan!$EE$9:$EE$528,$I$1)) -> 0 | M62: =IF($I$1=0,0,INDEX(Plan!$EF$9:$EF$528,$I$1)) -> 0 | N62: =IF($I$1=0,0,INDEX(Plan!$EG$9:$EG$528,$I$1)) -> 0 | O62: =IF($I$1=0,0,INDEX(Plan!$EH$9:$EH$528,$I$1)) -> 0 | P62: =IF($I$1=0,0,INDEX(Plan!$EI$9:$EI$528,$I$1)) -> 0 | Q62: =IF($I$1=0,0,INDEX(Plan!$EJ$9:$EJ$528,$I$1)) -> 0 | R62: =IF($I$1=0,0,INDEX(Plan!$EK$9:$EK$528,$I$1)) -> 0 | S62: =IF($I$1=0,0,INDEX(Plan!$EL$9:$EL$528,$I$1)) -> 0 | T62: =IF($I$1=0,0,INDEX(Plan!$EM$9:$EM$528,$I$1)) -> 0 | U62: =IF($I$1=0,0,INDEX(Plan!$EN$9:$EN$528,$I$1)) -> 0 | V62: =IF($I$1=0,0,INDEX(Plan!$EO$9:$EO$528,$I$1)) -> 0 | W62: =IF($I$1=0,0,INDEX(Plan!$EP$9:$EP$528,$I$1)) -> 0 | X62: =IF($I$1=0,0,INDEX(Plan!$EQ$9:$EQ$528,$I$1)) -> 0 | Y62: =IF($I$1=0,0,INDEX(Plan!$ER$9:$ER$528,$I$1)) -> 0 | Z62: =IF($I$1=0,0,INDEX(Plan!$ES$9:$ES$528,$I$1)) -> 0 | AA62: =IF($I$1=0,0,INDEX(Plan!$ET$9:$ET$528,$I$1)) -> 0 | AB62: =IF($I$1=0,0,INDEX(Plan!$EU$9:$EU$528,$I$1)) -> 0 | AC62: =IF($I$1=0,0,INDEX(Plan!$EV$9:$EV$528,$I$1)) -> 0 | AD62: =IF($I$1=0,0,INDEX(Plan!$EW$9:$EW$528,$I$1)) -> 0 | AE62: =IF($I$1=0,0,INDEX(Plan!$EX$9:$EX$528,$I$1)) -> 0 | AF62: =IF($I$1=0,0,INDEX(Plan!$EY$9:$EY$528,$I$1)) -> 0 | AG62: =IF($I$1=0,0,INDEX(Plan!$EZ$9:$EZ$528,$I$1)) -> 0 | AH62: =IF($I$1=0,0,INDEX(Plan!$FA$9:$FA$528,$I$1)) -> 0 | AI62: =IF($I$1=0,0,INDEX(Plan!$FB$9:$FB$528,$I$1)) -> 0 | AJ62: =IF($I$1=0,0,INDEX(Plan!$FC$9:$FC$528,$I$1)) -> 0 | AK62: =IF($I$1=0,0,INDEX(Plan!$FD$9:$FD$528,$I$1)) -> 0 | AL62: =IF($I$1=0,0,INDEX(Plan!$FE$9:$FE$528,$I$1)) -> 0 | AM62: =IF($I$1=0,0,INDEX(Plan!$FF$9:$FF$528,$I$1)) -> 0 | AN62: =IF($I$1=0,0,INDEX(Plan!$FG$9:$FG$528,$I$1)) -> 0 | AO62: =IF($I$1=0,0,INDEX(Plan!$FH$9:$FH$528,$I$1)) -> 0 | AP62: =IF($I$1=0,0,INDEX(Plan!$FI$9:$FI$528,$I$1)) -> 0 | AQ62: =IF($I$1=0,0,INDEX(Plan!$FJ$9:$FJ$528,$I$1)) -> 0 | AR62: =IF($I$1=0,0,INDEX(Plan!$FK$9:$FK$528,$I$1)) -> 0 | AS62: =IF($I$1=0,0,INDEX(Plan!$FL$9:$FL$528,$I$1)) -> 0 | AT62: =IF($I$1=0,0,INDEX(Plan!$FM$9:$FM$528,$I$1)) -> 0 | AU62: =IF($I$1=0,0,INDEX(Plan!$FN$9:$FN$528,$I$1)) -> 0 | AV62: =IF($I$1=0,0,INDEX(Plan!$FO$9:$FO$528,$I$1)) -> 0 | AW62: =IF($I$1=0,0,INDEX(Plan!$FP$9:$FP$528,$I$1)) -> 0 | AX62: =IF($I$1=0,0,INDEX(Plan!$FQ$9:$FQ$528,$I$1)) -> 0 | AY62: =IF($I$1=0,0,INDEX(Plan!$FR$9:$FR$528,$I$1)) -> 0 | AZ62: =IF($I$1=0,0,INDEX(Plan!$FS$9:$FS$528,$I$1)) -> 0
C63: =IF(C61+C62>0.005,1,0) -> 1 | D63: =IF(D61+D62>0.005,1,0) -> 0 | E63: =IF(E61+E62>0.005,1,0) -> 0 | F63: =IF(F61+F62>0.005,1,0) -> 0 | G63: =IF(G61+G62>0.005,1,0) -> 0 | H63: =IF(H61+H62>0.005,1,0) -> 0 | I63: =IF(I61+I62>0.005,1,0) -> 0 | J63: =IF(J61+J62>0.005,1,0) -> 0 | ... AZ63: =IF(AZ61+AZ62>0.005,1,0) -> 0
C64: =C63 -> 1 | D64: =C64+D63 -> 1 | E64: =D64+E63 -> 1 | F64: =E64+F63 -> 1 | G64: =F64+G63 -> 1 | H64: =G64+H63 -> 1 | I64: =H64+I63 -> 1 | J64: =I64+J63 -> 1 | K64: =J64+K63 -> 1 | ... AZ64: =AY64+AZ63 -> 1
