Workbook

Sheet Start Here
B1: Paycheck Payoff Planner
B2: PaidInYellow · One paycheck at a time.
C4: Works best on a computer. On your phone, open the Today tab: it shows your next payday on one screen.
B5: First time (about 15 minutes)
B6: 1 | C6: If you opened this from our link, go to File > Make a copy, and work in your copy.
B7: 2 | C7: Setup: how often you get paid, your next payday, and how much you can put toward the plan each payday on top of your minimums.
B8: 3 | C8: Debts: add every debt with its balance, interest rate, monthly minimum and due day. There is room for 50. Include the ones you would rather forget.
B9: 4 | C9: Yearly Bills: add the bills that come once or twice a year, like car repairs or holiday gifts. The sheet splits each one into a small amount per payday.
B10: 5 | C10: Dashboard: your debt-free date is at the top. The sample numbers are there to show how it works, so replace them with yours.
B12: Every payday (about 10 minutes)
B13: 1 | C13: On your phone, open the Today tab. It shows this payday on one screen. On a computer, Paycheck Plan shows every payday.
B14: 2 | C14: Make the payments in that row: minimums, buffer, yearly bills, and the extra payment to the debt it names.
B15: 3 | C15: Paid more or less than usual this time? Type the difference in "+/- this payday", for example 80 or -50.
B16: 4 | C16: Anything new go on a card? Type the amount in "New charges" and pick a type. Nobody sees this but you.
B17: 5 | C17: Choose "Paid" in the Paid? column, right next to the date. The row turns yellow.
B19: Once a month
C20: Check your real balances against the sheet. If they have drifted, type today's balances on Debts, set your next payday on Setup, and clear the Paid, +/- and New charges columns. The plan then starts fresh from today.
B22: Colors
C23: White cells: type here.
C24: Cream cells: the sheet fills these in. Leave them alone.
C25: Yellow: paid.
B27: Good to know
C28: Your buffer comes first. Until it reaches your goal, the extra money goes there, so one surprise bill doesn't land back on a card.
C29: The math is an estimate. Lenders work out interest a little differently and the sheet plans per payday, so real balances will be close but not exact. The monthly check keeps it honest.
C30: Payoff order: "PaidInYellow order" clears the smallest balance first, except a debt whose minimum doesn't cover its interest, which goes first because it grows. "Biggest interest first" usually costs less in total. "My own order" follows the numbers you type on Debts.
C31: If the minimums are more than you can pay, read "When the plan isn't enough" in the Never Back in Debt Guide, or call a nonprofit credit counselor (NFCC.org in the US). This sheet helps you plan and isn't financial advice.
C33: For your personal use. Please don't share or resell this file.
C34: PaidInYellow · paidinyellow.com · help@paidinyellow.com

Sheet Today
B1: Today
B2: Your next payday on one screen.
B4: Debt-free by | C4: =Dashboard!B5
B5: Next payday | C5: =IF(INDEX('Paycheck Plan'!$A$7:$A$526,Engine!$D$1)="","All paid",INDEX('Paycheck Plan'!$B$7:$B$526,Engine!$D$1))
B6: Payday number | C6: =IF(INDEX('Paycheck Plan'!$A$7:$A$526,Engine!$D$1)="","",INDEX('Paycheck Plan'!$A$7:$A$526,Engine!$D$1))
B8: Pay or move this payday
B9: 1. Minimum payments | C9: =IF(INDEX('Paycheck Plan'!$A$7:$A$526,Engine!$D$1)="","",Setup!$C$5&TEXT(INDEX('Paycheck Plan'!$G$7:$G$526,Engine!$D$1),"#,##0.00"))
B10: The smallest payment each debt asks for. Autopay usually takes care of these.
B11: 2. Move to your buffer | C11: =IF(INDEX('Paycheck Plan'!$A$7:$A$526,Engine!$D$1)="","",Setup!$C$5&TEXT(INDEX('Paycheck Plan'!$H$7:$H$526,Engine!$D$1),"#,##0.00"))
B12: Savings for surprise bills, in a separate account.
B13: 3. Move to yearly bills | C13: =IF(INDEX('Paycheck Plan'!$A$7:$A$526,Engine!$D$1)="","",Setup!$C$5&TEXT(INDEX('Paycheck Plan'!$I$7:$I$526,Engine!$D$1),"#,##0.00"))
B14: A little each payday for bills like car repairs and gifts.
B15: 4. Extra payment | C15: =IF(INDEX('Paycheck Plan'!$A$7:$A$526,Engine!$D$1)="","",Setup!$C$5&TEXT(INDEX('Paycheck Plan'!$E$7:$E$526,Engine!$D$1),"#,##0.00"))
B16: =IF(INDEX('Paycheck Plan'!$A$7:$A$526,Engine!$D$1)="","",IF(INDEX('Paycheck Plan'!$E$7:$E$526,Engine!$D$1)>0.005,"Send it to "&INDEX('Paycheck Plan'!$F$7:$F$526,Engine!$D$1)&". All the extra goes to this one debt.","No extra this time. Your buffer fills first."))
B17: Total | C17: =IF(INDEX('Paycheck Plan'!$A$7:$A$526,Engine!$D$1)="","",Setup!$C$5&TEXT(INDEX('Paycheck Plan'!$D$7:$D$526,Engine!$D$1),"#,##0.00"))
B19: =IF(INDEX('Paycheck Plan'!$A$7:$A$526,Engine!$D$1)="","Every debt is paid.","Done? Open Paycheck Plan, find payday "&INDEX('Paycheck Plan'!$A$7:$A$526,Engine!$D$1)&" and choose Paid.")
B21: Where you are
B22: Debt left | C22: =Setup!$C$5&TEXT(INDEX(Engine!$J$10:$J$530,Engine!$D$1),"#,##0")
B23: Debt gone | C23: =IFERROR(1-INDEX(Engine!$J$10:$J$530,Engine!$D$1)/Engine!$J$10,1)
B24: Buffer | C24: =Setup!$C$5&TEXT(INDEX(Engine!$F$10:$F$530,Engine!$D$1),"#,##0")&" of "&Setup!$C$5&TEXT(Setup!$C$10,"#,##0")
B25: Interest per day | C25: =Setup!$C$5&TEXT(SUMPRODUCT(INDEX(Engine!$T$10:$BQ$530,Engine!$D$1,0),Engine!$T$6:$BQ$6)/365,"#,##0.00")
B26: What your debts cost you each day right now. It drops as balances go down.

Sheet Dashboard
B1: Your debt-free dashboard
B2: Updates every time you mark a payday Paid.
B4: You'll be debt-free by
B5: =IFERROR(INDEX(Engine!$B$10:$B$530,Engine!$B$2+1),"More than 20 years. See Compare.")
B6: =IF(Engine!$B$2-Engine!$B$1<=0,"Every debt is paid.","That's "&(Engine!$B$2-Engine!$B$1)&" paydays from now, one paycheck at a time.")
B8: This payday
B9: =IF(INDEX('Paycheck Plan'!$A$7:$A$526,Engine!$D$1)="","Nothing left to pay. Keep your buffer and yearly bills going.",TEXT(INDEX('Paycheck Plan'!$B$7:$B$526,Engine!$D$1),"mmm d")&": set aside "&Setup!$C$5&TEXT(INDEX('Paycheck Plan'!$D$7:$D$526,Engine!$D$1),"#,##0")&" in total. "&IF(INDEX('Paycheck Plan'!$E$7:$E$526,Engine!$D$1)>0.005,"Your extra payment is "&Setup!$C$5&TEXT(INDEX('Paycheck Plan'!$E$7:$E$526,Engine!$D$1),"#,##0")&" to "&INDEX('Paycheck Plan'!$F$7:$F$526,Engine!$D$1)&".","This one fills your buffer, so there's no extra payment yet."))
B12: Debt left | G12: Paid off so far | L12: Interest per day right now | Q12: Paydays left
B13: =Setup!$C$5&TEXT(INDEX(Engine!$J$10:$J$530,Engine!$D$1),"#,##0") | G13: =Setup!$C$5&TEXT(MAX(0,Engine!$J$10-INDEX(Engine!$J$10:$J$530,Engine!$D$1)),"#,##0") | L13: =Setup!$C$5&TEXT(SUMPRODUCT(INDEX(Engine!$T$10:$BQ$530,Engine!$D$1,0),Engine!$T$6:$BQ$6)/365,"#,##0.00") | Q13: =MAX(0,Engine!$B$2-Engine!$B$1)
B15: ="Debt gone: "&TEXT(IFERROR(1-INDEX(Engine!$J$10:$J$530,Engine!$D$1)/Engine!$J$10,1),"0%")
W16: =IFERROR(1-INDEX(Engine!$J$10:$J$530,Engine!$D$1)/Engine!$J$10,1)
B18: =IF(INDEX('Paycheck Plan'!$A$7:$A$526,Engine!$D$1)="","Focus debt: all done","Focus debt: "&INDEX(Engine!$T$4:$BQ$4,INDEX(Engine!$K$11:$K$530,Engine!$D$1))&", "&TEXT(IFERROR(MAX(0,1-INDEX(Engine!$T$10:$BQ$530,Engine!$D$1,INDEX(Engine!$K$11:$K$530,Engine!$D$1))/INDEX(Engine!$T$5:$BQ$5,INDEX(Engine!$K$11:$K$530,Engine!$D$1))),1),"0%")&" paid")
W19: =IFERROR(MAX(0,1-INDEX(Engine!$T$10:$BQ$530,Engine!$D$1,INDEX(Engine!$K$11:$K$530,Engine!$D$1))/INDEX(Engine!$T$5:$BQ$5,INDEX(Engine!$K$11:$K$530,Engine!$D$1))),1)
B21: ="Buffer: "&Setup!$C$5&TEXT(INDEX(Engine!$F$10:$F$530,Engine!$D$1),"#,##0")&" of "&Setup!$C$5&TEXT(Setup!$C$10,"#,##0")
W22: =IFERROR(MIN(1,INDEX(Engine!$F$10:$F$530,Engine!$D$1)/Setup!$C$10),1)
B24: Interest on your plan | G24: Interest paying minimums only | L24: Interest you avoid | Q24: Yearly bills per payday
B25: =Setup!$C$5&TEXT(SUM(Engine!$I$11:$I$530),"#,##0") | G25: =IF(COUNTIF(Debts!$L$6:$L$55,"Never")>0,"Never ends",Setup!$C$5&TEXT(SUM(Debts!$L$6:$L$55),"#,##0")) | L25: =IF(COUNTIF(Debts!$L$6:$L$55,"Never")>0,"Your plan ends it",Setup!$C$5&TEXT(MAX(0,SUM(Debts!$L$6:$L$55)-SUM(Engine!$I$11:$I$530)),"#,##0")) | Q25: =Setup!$C$5&TEXT(Setup!$C$14,"#,##0")
B27: Where new charges came from
B28: Everyday | G28: Emergency | L28: One-off | Q28: Log charges on Paycheck Plan. The pattern shows where new debt comes from.
B29: =Setup!$C$5&TEXT(SUMIF('Paycheck Plan'!$L$7:$L$526,"Everyday",'Paycheck Plan'!$K$7:$K$526),"#,##0") | G29: =Setup!$C$5&TEXT(SUMIF('Paycheck Plan'!$L$7:$L$526,"Emergency",'Paycheck Plan'!$K$7:$K$526),"#,##0") | L29: =Setup!$C$5&TEXT(SUMIF('Paycheck Plan'!$L$7:$L$526,"One-off",'Paycheck Plan'!$K$7:$K$526),"#,##0")
B31: Debt left, payday by payday

Sheet Paycheck Plan
B1: Paycheck plan
B2: One row per payday. Make the payments, then choose Paid. The cream columns are worked out for you.
B4: Start at the first row that isn't yellow. If you skip a payday, do the next one. The date still moves.
A6: Payday | B6: Date | C6: Paid? | D6: Total to set aside | E6: Extra payment | F6: Extra goes to | G6: For minimums | H6: To buffer | I6: To yearly bills | J6: +/- this payday | K6: New charges | L6: Charge type | M6: Debt left after
A7: =IF(Engine!$J$10>0.005,Engine!A11,"") | B7: =IF($A7="","",Engine!B11) | D7: =IF($A7="","",G7+H7+I7+E7) | E7: =IF($A7="","",SUM(Engine!DP11:FM11)) | F7: =IF($A7="","",IF(E7>0.005,INDEX(Engine!$T$4:$BQ$4,Engine!K11),IF(H7>0,"Buffer first",""))) | G7: =IF($A7="","",SUM(Engine!BR11:DO11)) | H7: =IF($A7="","",Engine!E11) | I7: =IF($A7="","",Engine!G11) | M7: =IF($A7="","",Engine!J11)
A8: =IF(Engine!$J$11>0.005,Engine!A12,"") | B8: =IF($A8="","",Engine!B12) | D8: =IF($A8="","",G8+H8+I8+E8) | E8: =IF($A8="","",SUM(Engine!DP12:FM12)) | F8: =IF($A8="","",IF(E8>0.005,INDEX(Engine!$T$4:$BQ$4,Engine!K12),IF(H8>0,"Buffer first",""))) | G8: =IF($A8="","",SUM(Engine!BR12:DO12)) | H8: =IF($A8="","",Engine!E12) | I8: =IF($A8="","",Engine!G12) | M8: =IF($A8="","",Engine!J12)
A9: =IF(Engine!$J$12>0.005,Engine!A13,"") | B9: =IF($A9="","",Engine!B13) | D9: =IF($A9="","",G9+H9+I9+E9) | E9: =IF($A9="","",SUM(Engine!DP13:FM13)) | F9: =IF($A9="","",IF(E9>0.005,INDEX(Engine!$T$4:$BQ$4,Engine!K13),IF(H9>0,"Buffer first",""))) | G9: =IF($A9="","",SUM(Engine!BR13:DO13)) | H9: =IF($A9="","",Engine!E13) | I9: =IF($A9="","",Engine!G13) | M9: =IF($A9="","",Engine!J13)
A10: =IF(Engine!$J$13>0.005,Engine!A14,"") | B10: =IF($A10="","",Engine!B14) | D10: =IF($A10="","",G10+H10+I10+E10) | E10: =IF($A10="","",SUM(Engine!DP14:FM14)) | F10: =IF($A10="","",IF(E10>0.005,INDEX(Engine!$T$4:$BQ$4,Engine!K14),IF(H10>0,"Buffer first",""))) | G10: =IF($A10="","",SUM(Engine!BR14:DO14)) | H10: =IF($A10="","",Engine!E14) | I10: =IF($A10="","",Engine!G14) | M10: =IF($A10="","",Engine!J14)
A11: =IF(Engine!$J$14>0.005,Engine!A15,"") | B11: =IF($A11="","",Engine!B15) | D11: =IF($A11="","",G11+H11+I11+E11) | E11: =IF($A11="","",SUM(Engine!DP15:FM15)) | F11: =IF($A11="","",IF(E11>0.005,INDEX(Engine!$T$4:$BQ$4,Engine!K15),IF(H11>0,"Buffer first",""))) | G11: =IF($A11="","",SUM(Engine!BR15:DO15)) | H11: =IF($A11="","",Engine!E15) | I11: =IF($A11="","",Engine!G15) | M11: =IF($A11="","",Engine!J15)
A12: =IF(Engine!$J$15>0.005,Engine!A16,"") | B12: =IF($A12="","",Engine!B16) | D12: =IF($A12="","",G12+H12+I12+E12) | E12: =IF($A12="","",SUM(Engine!DP16:FM16)) | F12: =IF($A12="","",IF(E12>0.005,INDEX(Engine!$T$4:$BQ$4,Engine!K16),IF(H12>0,"Buffer first",""))) | G12: =IF($A12="","",SUM(Engine!BR16:DO16)) | H12: =IF($A12="","",Engine!E16) | I12: =IF($A12="","",Engine!G16) | M12: =IF($A12="","",Engine!J16)
A13: =IF(Engine!$J$16>0.005,Engine!A17,"") | B13: =IF($A13="","",Engine!B17) | D13: =IF($A13="","",G13+H13+I13+E13) | E13: =IF($A13="","",SUM(Engine!DP17:FM17)) | F13: =IF($A13="","",IF(E13>0.005,INDEX(Engine!$T$4:$BQ$4,Engine!K17),IF(H13>0,"Buffer first",""))) | G13: =IF($A13="","",SUM(Engine!BR17:DO17)) | H13: =IF($A13="","",Engine!E17) | I13: =IF($A13="","",Engine!G17) | M13: =IF($A13="","",Engine!J17)
A14: =IF(Engine!$J$17>0.005,Engine!A18,"") | B14: =IF($A14="","",Engine!B18) | D14: =IF($A14="","",G14+H14+I14+E14) | E14: =IF($A14="","",SUM(Engine!DP18:FM18)) | F14: =IF($A14="","",IF(E14>0.005,INDEX(Engine!$T$4:$BQ$4,Engine!K18),IF(H14>0,"Buffer first",""))) | G14: =IF($A14="","",SUM(Engine!BR18:DO18)) | H14: =IF($A14="","",Engine!E18) | I14: =IF($A14="","",Engine!G18) | M14: =IF($A14="","",Engine!J18)
A15: =IF(Engine!$J$18>0.005,Engine!A19,"") | B15: =IF($A15="","",Engine!B19) | D15: =IF($A15="","",G15+H15+I15+E15) | E15: =IF($A15="","",SUM(Engine!DP19:FM19)) | F15: =IF($A15="","",IF(E15>0.005,INDEX(Engine!$T$4:$BQ$4,Engine!K19),IF(H15>0,"Buffer first",""))) | G15: =IF($A15="","",SUM(Engine!BR19:DO19)) | H15: =IF($A15="","",Engine!E19) | I15: =IF($A15="","",Engine!G19) | M15: =IF($A15="","",Engine!J19)
A16: =IF(Engine!$J$19>0.005,Engine!A20,"") | B16: =IF($A16="","",Engine!B20) | D16: =IF($A16="","",G16+H16+I16+E16) | E16: =IF($A16="","",SUM(Engine!DP20:FM20)) | F16: =IF($A16="","",IF(E16>0.005,INDEX(Engine!$T$4:$BQ$4,Engine!K20),IF(H16>0,"Buffer first",""))) | G16: =IF($A16="","",SUM(Engine!BR20:DO20)) | H16: =IF($A16="","",Engine!E20) | I16: =IF($A16="","",Engine!G20) | M16: =IF($A16="","",Engine!J20)
A17: =IF(Engine!$J$20>0.005,Engine!A21,"") | B17: =IF($A17="","",Engine!B21) | D17: =IF($A17="","",G17+H17+I17+E17) | E17: =IF($A17="","",SUM(Engine!DP21:FM21)) | F17: =IF($A17="","",IF(E17>0.005,INDEX(Engine!$T$4:$BQ$4,Engine!K21),IF(H17>0,"Buffer first",""))) | G17: =IF($A17="","",SUM(Engine!BR21:DO21)) | H17: =IF($A17="","",Engine!E21) | I17: =IF($A17="","",Engine!G21) | M17: =IF($A17="","",Engine!J21)
A18: =IF(Engine!$J$21>0.005,Engine!A22,"") | B18: =IF($A18="","",Engine!B22) | D18: =IF($A18="","",G18+H18+I18+E18) | E18: =IF($A18="","",SUM(Engine!DP22:FM22)) | F18: =IF($A18="","",IF(E18>0.005,INDEX(Engine!$T$4:$BQ$4,Engine!K22),IF(H18>0,"Buffer first",""))) | G18: =IF($A18="","",SUM(Engine!BR22:DO22)) | H18: =IF($A18="","",Engine!E22) | I18: =IF($A18="","",Engine!G22) | M18: =IF($A18="","",Engine!J22)
A19: =IF(Engine!$J$22>0.005,Engine!A23,"") | B19: =IF($A19="","",Engine!B23) | D19: =IF($A19="","",G19+H19+I19+E19) | E19: =IF($A19="","",SUM(Engine!DP23:FM23)) | F19: =IF($A19="","",IF(E19>0.005,INDEX(Engine!$T$4:$BQ$4,Engine!K23),IF(H19>0,"Buffer first",""))) | G19: =IF($A19="","",SUM(Engine!BR23:DO23)) | H19: =IF($A19="","",Engine!E23) | I19: =IF($A19="","",Engine!G23) | M19: =IF($A19="","",Engine!J23)
A20: =IF(Engine!$J$23>0.005,Engine!A24,"") | B20: =IF($A20="","",Engine!B24) | D20: =IF($A20="","",G20+H20+I20+E20) | E20: =IF($A20="","",SUM(Engine!DP24:FM24)) | F20: =IF($A20="","",IF(E20>0.005,INDEX(Engine!$T$4:$BQ$4,Engine!K24),IF(H20>0,"Buffer first",""))) | G20: =IF($A20="","",SUM(Engine!BR24:DO24)) | H20: =IF($A20="","",Engine!E24) | I20: =IF($A20="","",Engine!G24) | M20: =IF($A20="","",Engine!J24)
A21: =IF(Engine!$J$24>0.005,Engine!A25,"") | B21: =IF($A21="","",Engine!B25) | D21: =IF($A21="","",G21+H21+I21+E21) | E21: =IF($A21="","",SUM(Engine!DP25:FM25)) | F21: =IF($A21="","",IF(E21>0.005,INDEX(Engine!$T$4:$BQ$4,Engine!K25),IF(H21>0,"Buffer first",""))) | G21: =IF($A21="","",SUM(Engine!BR25:DO25)) | H21: =IF($A21="","",Engine!E25) | I21: =IF($A21="","",Engine!G25) | M21: =IF($A21="","",Engine!J25)
A22: =IF(Engine!$J$25>0.005,Engine!A26,"") | B22: =IF($A22="","",Engine!B26) | D22: =IF($A22="","",G22+H22+I22+E22) | E22: =IF($A22="","",SUM(Engine!DP26:FM26)) | F22: =IF($A22="","",IF(E22>0.005,INDEX(Engine!$T$4:$BQ$4,Engine!K26),IF(H22>0,"Buffer first",""))) | G22: =IF($A22="","",SUM(Engine!BR26:DO26)) | H22: =IF($A22="","",Engine!E26) | I22: =IF($A22="","",Engine!G26) | M22: =IF($A22="","",Engine!J26)
A23: =IF(Engine!$J$26>0.005,Engine!A27,"") | B23: =IF($A23="","",Engine!B27) | D23: =IF($A23="","",G23+H23+I23+E23) | E23: =IF($A23="","",SUM(Engine!DP27:FM27)) | F23: =IF($A23="","",IF(E23>0.005,INDEX(Engine!$T$4:$BQ$4,Engine!K27),IF(H23>0,"Buffer first",""))) | G23: =IF($A23="","",SUM(Engine!BR27:DO27)) | H23: =IF($A23="","",Engine!E27) | I23: =IF($A23="","",Engine!G27) | M23: =IF($A23="","",Engine!J27)
A24: =IF(Engine!$J$27>0.005,Engine!A28,"") | B24: =IF($A24="","",Engine!B28) | D24: =IF($A24="","",G24+H24+I24+E24) | E24: =IF($A24="","",SUM(Engine!DP28:FM28)) | F24: =IF($A24="","",IF(E24>0.005,INDEX(Engine!$T$4:$BQ$4,Engine!K28),IF(H24>0,"Buffer first",""))) | G24: =IF($A24="","",SUM(Engine!BR28:DO28)) | H24: =IF($A24="","",Engine!E28) | I24: =IF($A24="","",Engine!G28) | M24: =IF($A24="","",Engine!J28)
A25: =IF(Engine!$J$28>0.005,Engine!A29,"") | B25: =IF($A25="","",Engine!B29) | D25: =IF($A25="","",G25+H25+I25+E25) | E25: =IF($A25="","",SUM(Engine!DP29:FM29)) | F25: =IF($A25="","",IF(E25>0.005,INDEX(Engine!$T$4:$BQ$4,Engine!K29),IF(H25>0,"Buffer first",""))) | G25: =IF($A25="","",SUM(Engine!BR29:DO29)) | H25: =IF($A25="","",Engine!E29) | I25: =IF($A25="","",Engine!G29) | M25: =IF($A25="","",Engine!J29)
A26: =IF(Engine!$J$29>0.005,Engine!A30,"") | B26: =IF($A26="","",Engine!B30) | D26: =IF($A26="","",G26+H26+I26+E26) | E26: =IF($A26="","",SUM(Engine!DP30:FM30)) | F26: =IF($A26="","",IF(E26>0.005,INDEX(Engine!$T$4:$BQ$4,Engine!K30),IF(H26>0,"Buffer first",""))) | G26: =IF($A26="","",SUM(Engine!BR30:DO30)) | H26: =IF($A26="","",Engine!E30) | I26: =IF($A26="","",Engine!G30) | M26: =IF($A26="","",Engine!J30)
A27: =IF(Engine!$J$30>0.005,Engine!A31,"") | B27: =IF($A27="","",Engine!B31) | D27: =IF($A27="","",G27+H27+I27+E27) | E27: =IF($A27="","",SUM(Engine!DP31:FM31)) | F27: =IF($A27="","",IF(E27>0.005,INDEX(Engine!$T$4:$BQ$4,Engine!K31),IF(H27>0,"Buffer first",""))) | G27: =IF($A27="","",SUM(Engine!BR31:DO31)) | H27: =IF($A27="","",Engine!E31) | I27: =IF($A27="","",Engine!G31) | M27: =IF($A27="","",Engine!J31)
A28: =IF(Engine!$J$31>0.005,Engine!A32,"") | B28: =IF($A28="","",Engine!B32) | D28: =IF($A28="","",G28+H28+I28+E28) | E28: =IF($A28="","",SUM(Engine!DP32:FM32)) | F28: =IF($A28="","",IF(E28>0.005,INDEX(Engine!$T$4:$BQ$4,Engine!K32),IF(H28>0,"Buffer first",""))) | G28: =IF($A28="","",SUM(Engine!BR32:DO32)) | H28: =IF($A28="","",Engine!E32) | I28: =IF($A28="","",Engine!G32) | M28: =IF($A28="","",Engine!J32)
A29: =IF(Engine!$J$32>0.005,Engine!A33,"") | B29: =IF($A29="","",Engine!B33) | D29: =IF($A29="","",G29+H29+I29+E29) | E29: =IF($A29="","",SUM(Engine!DP33:FM33)) | F29: =IF($A29="","",IF(E29>0.005,INDEX(Engine!$T$4:$BQ$4,Engine!K33),IF(H29>0,"Buffer first",""))) | G29: =IF($A29="","",SUM(Engine!BR33:DO33)) | H29: =IF($A29="","",Engine!E33) | I29: =IF($A29="","",Engine!G33) | M29: =IF($A29="","",Engine!J33)
A30: =IF(Engine!$J$33>0.005,Engine!A34,"") | B30: =IF($A30="","",Engine!B34) | D30: =IF($A30="","",G30+H30+I30+E30) | E30: =IF($A30="","",SUM(Engine!DP34:FM34)) | F30: =IF($A30="","",IF(E30>0.005,INDEX(Engine!$T$4:$BQ$4,Engine!K34),IF(H30>0,"Buffer first",""))) | G30: =IF($A30="","",SUM(Engine!BR34:DO34)) | H30: =IF($A30="","",Engine!E34) | I30: =IF($A30="","",Engine!G34) | M30: =IF($A30="","",Engine!J34)
A31: =IF(Engine!$J$34>0.005,Engine!A35,"") | B31: =IF($A31="","",Engine!B35) | D31: =IF($A31="","",G31+H31+I31+E31) | E31: =IF($A31="","",SUM(Engine!DP35:FM35)) | F31: =IF($A31="","",IF(E31>0.005,INDEX(Engine!$T$4:$BQ$4,Engine!K35),IF(H31>0,"Buffer first",""))) | G31: =IF($A31="","",SUM(Engine!BR35:DO35)) | H31: =IF($A31="","",Engine!E35) | I31: =IF($A31="","",Engine!G35) | M31: =IF($A31="","",Engine!J35)
A32: =IF(Engine!$J$35>0.005,Engine!A36,"") | B32: =IF($A32="","",Engine!B36) | D32: =IF($A32="","",G32+H32+I32+E32) | E32: =IF($A32="","",SUM(Engine!DP36:FM36)) | F32: =IF($A32="","",IF(E32>0.005,INDEX(Engine!$T$4:$BQ$4,Engine!K36),IF(H32>0,"Buffer first",""))) | G32: =IF($A32="","",SUM(Engine!BR36:DO36)) | H32: =IF($A32="","",Engine!E36) | I32: =IF($A32="","",Engine!G36) | M32: =IF($A32="","",Engine!J36)
A33: =IF(Engine!$J$36>0.005,Engine!A37,"") | B33: =IF($A33="","",Engine!B37) | D33: =IF($A33="","",G33+H33+I33+E33) | E33: =IF($A33="","",SUM(Engine!DP37:FM37)) | F33: =IF($A33="","",IF(E33>0.005,INDEX(Engine!$T$4:$BQ$4,Engine!K37),IF(H33>0,"Buffer first",""))) | G33: =IF($A33="","",SUM(Engine!BR37:DO37)) | H33: =IF($A33="","",Engine!E37) | I33: =IF($A33="","",Engine!G37) | M33: =IF($A33="","",Engine!J37)
A34: =IF(Engine!$J$37>0.005,Engine!A38,"") | B34: =IF($A34="","",Engine!B38) | D34: =IF($A34="","",G34+H34+I34+E34) | E34: =IF($A34="","",SUM(Engine!DP38:FM38)) | F34: =IF($A34="","",IF(E34>0.005,INDEX(Engine!$T$4:$BQ$4,Engine!K38),IF(H34>0,"Buffer first",""))) | G34: =IF($A34="","",SUM(Engine!BR38:DO38)) | H34: =IF($A34="","",Engine!E38) | I34: =IF($A34="","",Engine!G38) | M34: =IF($A34="","",Engine!J38)
A35: =IF(Engine!$J$38>0.005,Engine!A39,"") | B35: =IF($A35="","",Engine!B39) | D35: =IF($A35="","",G35+H35+I35+E35) | E35: =IF($A35="","",SUM(Engine!DP39:FM39)) | F35: =IF($A35="","",IF(E35>0.005,INDEX(Engine!$T$4:$BQ$4,Engine!K39),IF(H35>0,"Buffer first",""))) | G35: =IF($A35="","",SUM(Engine!BR39:DO39)) | H35: =IF($A35="","",Engine!E39) | I35: =IF($A35="","",Engine!G39) | M35: =IF($A35="","",Engine!J39)
A36: =IF(Engine!$J$39>0.005,Engine!A40,"") | B36: =IF($A36="","",Engine!B40) | D36: =IF($A36="","",G36+H36+I36+E36) | E36: =IF($A36="","",SUM(Engine!DP40:FM40)) | F36: =IF($A36="","",IF(E36>0.005,INDEX(Engine!$T$4:$BQ$4,Engine!K40),IF(H36>0,"Buffer first",""))) | G36: =IF($A36="","",SUM(Engine!BR40:DO40)) | H36: =IF($A36="","",Engine!E40) | I36: =IF($A36="","",Engine!G40) | M36: =IF($A36="","",Engine!J40)
A37: =IF(Engine!$J$40>0.005,Engine!A41,"") | B37: =IF($A37="","",Engine!B41) | D37: =IF($A37="","",G37+H37+I37+E37) | E37: =IF($A37="","",SUM(Engine!DP41:FM41)) | F37: =IF($A37="","",IF(E37>0.005,INDEX(Engine!$T$4:$BQ$4,Engine!K41),IF(H37>0,"Buffer first",""))) | G37: =IF($A37="","",SUM(Engine!BR41:DO41)) | H37: =IF($A37="","",Engine!E41) | I37: =IF($A37="","",Engine!G41) | M37: =IF($A37="","",Engine!J41)
A38: =IF(Engine!$J$41>0.005,Engine!A42,"") | B38: =IF($A38="","",Engine!B42) | D38: =IF($A38="","",G38+H38+I38+E38) | E38: =IF($A38="","",SUM(Engine!DP42:FM42)) | F38: =IF($A38="","",IF(E38>0.005,INDEX(Engine!$T$4:$BQ$4,Engine!K42),IF(H38>0,"Buffer first",""))) | G38: =IF($A38="","",SUM(Engine!BR42:DO42)) | H38: =IF($A38="","",Engine!E42) | I38: =IF($A38="","",Engine!G42) | M38: =IF($A38="","",Engine!J42)
A39: =IF(Engine!$J$42>0.005,Engine!A43,"") | B39: =IF($A39="","",Engine!B43) | D39: =IF($A39="","",G39+H39+I39+E39) | E39: =IF($A39="","",SUM(Engine!DP43:FM43)) | F39: =IF($A39="","",IF(E39>0.005,INDEX(Engine!$T$4:$BQ$4,Engine!K43),IF(H39>0,"Buffer first",""))) | G39: =IF($A39="","",SUM(Engine!BR43:DO43)) | H39: =IF($A39="","",Engine!E43) | I39: =IF($A39="","",Engine!G43) | M39: =IF($A39="","",Engine!J43)
A40: =IF(Engine!$J$43>0.005,Engine!A44,"") | B40: =IF($A40="","",Engine!B44) | D40: =IF($A40="","",G40+H40+I40+E40) | E40: =IF($A40="","",SUM(Engine!DP44:FM44)) | F40: =IF($A40="","",IF(E40>0.005,INDEX(Engine!$T$4:$BQ$4,Engine!K44),IF(H40>0,"Buffer first",""))) | G40: =IF($A40="","",SUM(Engine!BR44:DO44)) | H40: =IF($A40="","",Engine!E44) | I40: =IF($A40="","",Engine!G44) | M40: =IF($A40="","",Engine!J44)
A41: =IF(Engine!$J$44>0.005,Engine!A45,"") | B41: =IF($A41="","",Engine!B45) | D41: =IF($A41="","",G41+H41+I41+E41) | E41: =IF($A41="","",SUM(Engine!DP45:FM45)) | F41: =IF($A41="","",IF(E41>0.005,INDEX(Engine!$T$4:$BQ$4,Engine!K45),IF(H41>0,"Buffer first",""))) | G41: =IF($A41="","",SUM(Engine!BR45:DO45)) | H41: =IF($A41="","",Engine!E45) | I41: =IF($A41="","",Engine!G45) | M41: =IF($A41="","",Engine!J45)
A42: =IF(Engine!$J$45>0.005,Engine!A46,"") | B42: =IF($A42="","",Engine!B46) | D42: =IF($A42="","",G42+H42+I42+E42) | E42: =IF($A42="","",SUM(Engine!DP46:FM46)) | F42: =IF($A42="","",IF(E42>0.005,INDEX(Engine!$T$4:$BQ$4,Engine!K46),IF(H42>0,"Buffer first",""))) | G42: =IF($A42="","",SUM(Engine!BR46:DO46)) | H42: =IF($A42="","",Engine!E46) | I42: =IF($A42="","",Engine!G46) | M42: =IF($A42="","",Engine!J46)
...

Sheet Setup
B1: Setup
B2: Fill in the white cells. Everything else updates on its own.
B5: Currency symbol | C5: $ | D5: Any symbol works: $, £, €, MAD.
B6: How often you get paid | C6: Every 2 weeks | D6: Paid twice a month? Fill in your other payday below.
B7: Your next payday | C7: 46318 | D7: The plan starts here. Change it when you restart the plan.
B8: Money for the plan each payday | C8: 150 | D8: On top of your minimums. It pays yearly bills, then your buffer, then extra to debt.
B9: Buffer saved right now | C9: 200 | D9: Money set aside for surprises, in a plain separate account.
B10: Buffer goal | C10: 500 | D10: $500 is a good first goal. You can raise it later.
B11: Payoff order | C11: PaidInYellow order | D11: See Start Here for what each one does.
B12: Twice a month only: your other payday | D12: Day of the month, 1 to 31 (31 = last day). Example: paid on the 15th and the last day, next payday Oct 31: type 15.
B13: Paydays per year | C13: =IF(C6="Every week",52,IF(C6="Every 2 weeks",26,IF(C6="Twice a month",24,12)))
B14: Yearly bills, set aside per payday | C14: ='Yearly Bills'!E27
B15: Order number (used by the sheet) | C15: =IF(C11="Biggest interest first",2,IF(C11="My own order",3,1))
B16: Next payday as a day (31 = last day) | C16: =IF(C7=EOMONTH(C7,0),31,DAY(C7))
B17: Other payday used | C17: =IF(OR(N(C12)<1,N(C12)>31,N(C12)=C16),IF(C16<=15,C16+15,IF(C16=31,15,C16-15)),INT(C12))
B18: Earlier pay day | C18: =MIN(C16,C17)
B19: Later pay day | C19: =MAX(C16,C17)
B20: Next payday is the later one (1 = yes) | C20: =IF(C16=C18,0,1)

Sheet Debts
B1: Your debts
B2: Every debt, one per row. Balances as of today. The cream columns fill in by themselves.
B5: Name | C5: Type | D5: Balance | E5: Interest rate % | F5: Monthly minimum | G5: Due day | H5: My order | I5: Payoff order | J5: Paid off by | K5: Months at minimums only | L5: Interest at minimums only | M5: Interest per day | N5: key
B6: Visa | C6: Credit card | D6: 3200 | E6: 22.9 | F6: 96 | G6: 12 | I6: =IF(B6="","",RANK(N6,$N$6:$N$55,1)) | J6: =IF(B6="","",IF(N(D6)<=0,"Paid",IFERROR(INDEX(Engine!$B$10:$B$530,COUNTIF(INDEX(Engine!$T$10:$BQ$530,0,I6),">0.005")+1),"20+ years"))) | K6: =IF(B6="","",IF(N(D6)<=0,0,IF(F6<=D6*E6/1200,"Never",IF(N(E6)=0,ROUNDUP(D6/F6,0),ROUNDUP(NPER(E6/1200,-F6,D6),0))))) | L6: =IF(B6="","",IF(K6="Never","Never",IF(OR(N(E6)=0,N(D6)<=0),0,F6*NPER(E6/1200,-F6,D6)-D6))) | M6: =IF(B6="","",N(D6)*N(E6)/100/365) | N6: =IF(B6="",1E12+ROW(),CHOOSE(Setup!$C$15,IF(AND(N(E6)>0,F6<=D6*E6/1200),-1E9-E6,D6),-E6*1E6+D6/1E6,IF(H6="",1E6,H6)))+ROW()/1E7
B7: Store card | C7: Store card | D7: 640 | E7: 26.99 | F7: 35 | G7: 5 | I7: =IF(B7="","",RANK(N7,$N$6:$N$55,1)) | J7: =IF(B7="","",IF(N(D7)<=0,"Paid",IFERROR(INDEX(Engine!$B$10:$B$530,COUNTIF(INDEX(Engine!$T$10:$BQ$530,0,I7),">0.005")+1),"20+ years"))) | K7: =IF(B7="","",IF(N(D7)<=0,0,IF(F7<=D7*E7/1200,"Never",IF(N(E7)=0,ROUNDUP(D7/F7,0),ROUNDUP(NPER(E7/1200,-F7,D7),0))))) | L7: =IF(B7="","",IF(K7="Never","Never",IF(OR(N(E7)=0,N(D7)<=0),0,F7*NPER(E7/1200,-F7,D7)-D7))) | M7: =IF(B7="","",N(D7)*N(E7)/100/365) | N7: =IF(B7="",1E12+ROW(),CHOOSE(Setup!$C$15,IF(AND(N(E7)>0,F7<=D7*E7/1200),-1E9-E7,D7),-E7*1E6+D7/1E6,IF(H7="",1E6,H7)))+ROW()/1E7
B8: Car loan | C8: Car loan | D8: 9800 | E8: 7.5 | F8: 285 | G8: 20 | I8: =IF(B8="","",RANK(N8,$N$6:$N$55,1)) | J8: =IF(B8="","",IF(N(D8)<=0,"Paid",IFERROR(INDEX(Engine!$B$10:$B$530,COUNTIF(INDEX(Engine!$T$10:$BQ$530,0,I8),">0.005")+1),"20+ years"))) | K8: =IF(B8="","",IF(N(D8)<=0,0,IF(F8<=D8*E8/1200,"Never",IF(N(E8)=0,ROUNDUP(D8/F8,0),ROUNDUP(NPER(E8/1200,-F8,D8),0))))) | L8: =IF(B8="","",IF(K8="Never","Never",IF(OR(N(E8)=0,N(D8)<=0),0,F8*NPER(E8/1200,-F8,D8)-D8))) | M8: =IF(B8="","",N(D8)*N(E8)/100/365) | N8: =IF(B8="",1E12+ROW(),CHOOSE(Setup!$C$15,IF(AND(N(E8)>0,F8<=D8*E8/1200),-1E9-E8,D8),-E8*1E6+D8/1E6,IF(H8="",1E6,H8)))+ROW()/1E7
B9: Medical bill | C9: Medical | D9: 1150 | E9: 0 | F9: 50 | G9: 1 | I9: =IF(B9="","",RANK(N9,$N$6:$N$55,1)) | J9: =IF(B9="","",IF(N(D9)<=0,"Paid",IFERROR(INDEX(Engine!$B$10:$B$530,COUNTIF(INDEX(Engine!$T$10:$BQ$530,0,I9),">0.005")+1),"20+ years"))) | K9: =IF(B9="","",IF(N(D9)<=0,0,IF(F9<=D9*E9/1200,"Never",IF(N(E9)=0,ROUNDUP(D9/F9,0),ROUNDUP(NPER(E9/1200,-F9,D9),0))))) | L9: =IF(B9="","",IF(K9="Never","Never",IF(OR(N(E9)=0,N(D9)<=0),0,F9*NPER(E9/1200,-F9,D9)-D9))) | M9: =IF(B9="","",N(D9)*N(E9)/100/365) | N9: =IF(B9="",1E12+ROW(),CHOOSE(Setup!$C$15,IF(AND(N(E9)>0,F9<=D9*E9/1200),-1E9-E9,D9),-E9*1E6+D9/1E6,IF(H9="",1E6,H9)))+ROW()/1E7
I10: =IF(B10="","",RANK(N10,$N$6:$N$55,1)) | J10: =IF(B10="","",IF(N(D10)<=0,"Paid",IFERROR(INDEX(Engine!$B$10:$B$530,COUNTIF(INDEX(Engine!$T$10:$BQ$530,0,I10),">0.005")+1),"20+ years"))) | K10: =IF(B10="","",IF(N(D10)<=0,0,IF(F10<=D10*E10/1200,"Never",IF(N(E10)=0,ROUNDUP(D10/F10,0),ROUNDUP(NPER(E10/1200,-F10,D10),0))))) | L10: =IF(B10="","",IF(K10="Never","Never",IF(OR(N(E10)=0,N(D10)<=0),0,F10*NPER(E10/1200,-F10,D10)-D10))) | M10: =IF(B10="","",N(D10)*N(E10)/100/365) | N10: =IF(B10="",1E12+ROW(),CHOOSE(Setup!$C$15,IF(AND(N(E10)>0,F10<=D10*E10/1200),-1E9-E10,D10),-E10*1E6+D10/1E6,IF(H10="",1E6,H10)))+ROW()/1E7
I11: =IF(B11="","",RANK(N11,$N$6:$N$55,1)) | J11: =IF(B11="","",IF(N(D11)<=0,"Paid",IFERROR(INDEX(Engine!$B$10:$B$530,COUNTIF(INDEX(Engine!$T$10:$BQ$530,0,I11),">0.005")+1),"20+ years"))) | K11: =IF(B11="","",IF(N(D11)<=0,0,IF(F11<=D11*E11/1200,"Never",IF(N(E11)=0,ROUNDUP(D11/F11,0),ROUNDUP(NPER(E11/1200,-F11,D11),0))))) | L11: =IF(B11="","",IF(K11="Never","Never",IF(OR(N(E11)=0,N(D11)<=0),0,F11*NPER(E11/1200,-F11,D11)-D11))) | M11: =IF(B11="","",N(D11)*N(E11)/100/365) | N11: =IF(B11="",1E12+ROW(),CHOOSE(Setup!$C$15,IF(AND(N(E11)>0,F11<=D11*E11/1200),-1E9-E11,D11),-E11*1E6+D11/1E6,IF(H11="",1E6,H11)))+ROW()/1E7
I12: =IF(B12="","",RANK(N12,$N$6:$N$55,1)) | J12: =IF(B12="","",IF(N(D12)<=0,"Paid",IFERROR(INDEX(Engine!$B$10:$B$530,COUNTIF(INDEX(Engine!$T$10:$BQ$530,0,I12),">0.005")+1),"20+ years"))) | K12: =IF(B12="","",IF(N(D12)<=0,0,IF(F12<=D12*E12/1200,"Never",IF(N(E12)=0,ROUNDUP(D12/F12,0),ROUNDUP(NPER(E12/1200,-F12,D12),0))))) | L12: =IF(B12="","",IF(K12="Never","Never",IF(OR(N(E12)=0,N(D12)<=0),0,F12*NPER(E12/1200,-F12,D12)-D12))) | M12: =IF(B12="","",N(D12)*N(E12)/100/365) | N12: =IF(B12="",1E12+ROW(),CHOOSE(Setup!$C$15,IF(AND(N(E12)>0,F12<=D12*E12/1200),-1E9-E12,D12),-E12*1E6+D12/1E6,IF(H12="",1E6,H12)))+ROW()/1E7
I13: =IF(B13="","",RANK(N13,$N$6:$N$55,1)) | J13: =IF(B13="","",IF(N(D13)<=0,"Paid",IFERROR(INDEX(Engine!$B$10:$B$530,COUNTIF(INDEX(Engine!$T$10:$BQ$530,0,I13),">0.005")+1),"20+ years"))) | K13: =IF(B13="","",IF(N(D13)<=0,0,IF(F13<=D13*E13/1200,"Never",IF(N(E13)=0,ROUNDUP(D13/F13,0),ROUNDUP(NPER(E13/1200,-F13,D13),0))))) | L13: =IF(B13="","",IF(K13="Never","Never",IF(OR(N(E13)=0,N(D13)<=0),0,F13*NPER(E13/1200,-F13,D13)-D13))) | M13: =IF(B13="","",N(D13)*N(E13)/100/365) | N13: =IF(B13="",1E12+ROW(),CHOOSE(Setup!$C$15,IF(AND(N(E13)>0,F13<=D13*E13/1200),-1E9-E13,D13),-E13*1E6+D13/1E6,IF(H13="",1E6,H13)))+ROW()/1E7
I14: =IF(B14="","",RANK(N14,$N$6:$N$55,1)) | J14: =IF(B14="","",IF(N(D14)<=0,"Paid",IFERROR(INDEX(Engine!$B$10:$B$530,COUNTIF(INDEX(Engine!$T$10:$BQ$530,0,I14),">0.005")+1),"20+ years"))) | K14: =IF(B14="","",IF(N(D14)<=0,0,IF(F14<=D14*E14/1200,"Never",IF(N(E14)=0,ROUNDUP(D14/F14,0),ROUNDUP(NPER(E14/1200,-F14,D14),0))))) | L14: =IF(B14="","",IF(K14="Never","Never",IF(OR(N(E14)=0,N(D14)<=0),0,F14*NPER(E14/1200,-F14,D14)-D14))) | M14: =IF(B14="","",N(D14)*N(E14)/100/365) | N14: =IF(B14="",1E12+ROW(),CHOOSE(Setup!$C$15,IF(AND(N(E14)>0,F14<=D14*E14/1200),-1E9-E14,D14),-E14*1E6+D14/1E6,IF(H14="",1E6,H14)))+ROW()/1E7
I15: =IF(B15="","",RANK(N15,$N$6:$N$55,1)) | J15: =IF(B15="","",IF(N(D15)<=0,"Paid",IFERROR(INDEX(Engine!$B$10:$B$530,COUNTIF(INDEX(Engine!$T$10:$BQ$530,0,I15),">0.005")+1),"20+ years"))) | K15: =IF(B15="","",IF(N(D15)<=0,0,IF(F15<=D15*E15/1200,"Never",IF(N(E15)=0,ROUNDUP(D15/F15,0),ROUNDUP(NPER(E15/1200,-F15,D15),0))))) | L15: =IF(B15="","",IF(K15="Never","Never",IF(OR(N(E15)=0,N(D15)<=0),0,F15*NPER(E15/1200,-F15,D15)-D15))) | M15: =IF(B15="","",N(D15)*N(E15)/100/365) | N15: =IF(B15="",1E12+ROW(),CHOOSE(Setup!$C$15,IF(AND(N(E15)>0,F15<=D15*E15/1200),-1E9-E15,D15),-E15*1E6+D15/1E6,IF(H15="",1E6,H15)))+ROW()/1E7
I16: =IF(B16="","",RANK(N16,$N$6:$N$55,1)) | J16: =IF(B16="","",IF(N(D16)<=0,"Paid",IFERROR(INDEX(Engine!$B$10:$B$530,COUNTIF(INDEX(Engine!$T$10:$BQ$530,0,I16),">0.005")+1),"20+ years"))) | K16: =IF(B16="","",IF(N(D16)<=0,0,IF(F16<=D16*E16/1200,"Never",IF(N(E16)=0,ROUNDUP(D16/F16,0),ROUNDUP(NPER(E16/1200,-F16,D16),0))))) | L16: =IF(B16="","",IF(K16="Never","Never",IF(OR(N(E16)=0,N(D16)<=0),0,F16*NPER(E16/1200,-F16,D16)-D16))) | M16: =IF(B16="","",N(D16)*N(E16)/100/365) | N16: =IF(B16="",1E12+ROW(),CHOOSE(Setup!$C$15,IF(AND(N(E16)>0,F16<=D16*E16/1200),-1E9-E16,D16),-E16*1E6+D16/1E6,IF(H16="",1E6,H16)))+ROW()/1E7
I17: =IF(B17="","",RANK(N17,$N$6:$N$55,1)) | J17: =IF(B17="","",IF(N(D17)<=0,"Paid",IFERROR(INDEX(Engine!$B$10:$B$530,COUNTIF(INDEX(Engine!$T$10:$BQ$530,0,I17),">0.005")+1),"20+ years"))) | K17: =IF(B17="","",IF(N(D17)<=0,0,IF(F17<=D17*E17/1200,"Never",IF(N(E17)=0,ROUNDUP(D17/F17,0),ROUNDUP(NPER(E17/1200,-F17,D17),0))))) | L17: =IF(B17="","",IF(K17="Never","Never",IF(OR(N(E17)=0,N(D17)<=0),0,F17*NPER(E17/1200,-F17,D17)-D17))) | M17: =IF(B17="","",N(D17)*N(E17)/100/365) | N17: =IF(B17="",1E12+ROW(),CHOOSE(Setup!$C$15,IF(AND(N(E17)>0,F17<=D17*E17/1200),-1E9-E17,D17),-E17*1E6+D17/1E6,IF(H17="",1E6,H17)))+ROW()/1E7
I18: =IF(B18="","",RANK(N18,$N$6:$N$55,1)) | J18: =IF(B18="","",IF(N(D18)<=0,"Paid",IFERROR(INDEX(Engine!$B$10:$B$530,COUNTIF(INDEX(Engine!$T$10:$BQ$530,0,I18),">0.005")+1),"20+ years"))) | K18: =IF(B18="","",IF(N(D18)<=0,0,IF(F18<=D18*E18/1200,"Never",IF(N(E18)=0,ROUNDUP(D18/F18,0),ROUNDUP(NPER(E18/1200,-F18,D18),0))))) | L18: =IF(B18="","",IF(K18="Never","Never",IF(OR(N(E18)=0,N(D18)<=0),0,F18*NPER(E18/1200,-F18,D18)-D18))) | M18: =IF(B18="","",N(D18)*N(E18)/100/365) | N18: =IF(B18="",1E12+ROW(),CHOOSE(Setup!$C$15,IF(AND(N(E18)>0,F18<=D18*E18/1200),-1E9-E18,D18),-E18*1E6+D18/1E6,IF(H18="",1E6,H18)))+ROW()/1E7
I19: =IF(B19="","",RANK(N19,$N$6:$N$55,1)) | J19: =IF(B19="","",IF(N(D19)<=0,"Paid",IFERROR(INDEX(Engine!$B$10:$B$530,COUNTIF(INDEX(Engine!$T$10:$BQ$530,0,I19),">0.005")+1),"20+ years"))) | K19: =IF(B19="","",IF(N(D19)<=0,0,IF(F19<=D19*E19/1200,"Never",IF(N(E19)=0,ROUNDUP(D19/F19,0),ROUNDUP(NPER(E19/1200,-F19,D19),0))))) | L19: =IF(B19="","",IF(K19="Never","Never",IF(OR(N(E19)=0,N(D19)<=0),0,F19*NPER(E19/1200,-F19,D19)-D19))) | M19: =IF(B19="","",N(D19)*N(E19)/100/365) | N19: =IF(B19="",1E12+ROW(),CHOOSE(Setup!$C$15,IF(AND(N(E19)>0,F19<=D19*E19/1200),-1E9-E19,D19),-E19*1E6+D19/1E6,IF(H19="",1E6,H19)))+ROW()/1E7
I20: =IF(B20="","",RANK(N20,$N$6:$N$55,1)) | J20: =IF(B20="","",IF(N(D20)<=0,"Paid",IFERROR(INDEX(Engine!$B$10:$B$530,COUNTIF(INDEX(Engine!$T$10:$BQ$530,0,I20),">0.005")+1),"20+ years"))) | K20: =IF(B20="","",IF(N(D20)<=0,0,IF(F20<=D20*E20/1200,"Never",IF(N(E20)=0,ROUNDUP(D20/F20,0),ROUNDUP(NPER(E20/1200,-F20,D20),0))))) | L20: =IF(B20="","",IF(K20="Never","Never",IF(OR(N(E20)=0,N(D20)<=0),0,F20*NPER(E20/1200,-F20,D20)-D20))) | M20: =IF(B20="","",N(D20)*N(E20)/100/365) | N20: =IF(B20="",1E12+ROW(),CHOOSE(Setup!$C$15,IF(AND(N(E20)>0,F20<=D20*E20/1200),-1E9-E20,D20),-E20*1E6+D20/1E6,IF(H20="",1E6,H20)))+ROW()/1E7
I21: =IF(B21="","",RANK(N21,$N$6:$N$55,1)) | J21: =IF(B21="","",IF(N(D21)<=0,"Paid",IFERROR(INDEX(Engine!$B$10:$B$530,COUNTIF(INDEX(Engine!$T$10:$BQ$530,0,I21),">0.005")+1),"20+ years"))) | K21: =IF(B21="","",IF(N(D21)<=0,0,IF(F21<=D21*E21/1200,"Never",IF(N(E21)=0,ROUNDUP(D21/F21,0),ROUNDUP(NPER(E21/1200,-F21,D21),0))))) | L21: =IF(B21="","",IF(K21="Never","Never",IF(OR(N(E21)=0,N(D21)<=0),0,F21*NPER(E21/1200,-F21,D21)-D21))) | M21: =IF(B21="","",N(D21)*N(E21)/100/365) | N21: =IF(B21="",1E12+ROW(),CHOOSE(Setup!$C$15,IF(AND(N(E21)>0,F21<=D21*E21/1200),-1E9-E21,D21),-E21*1E6+D21/1E6,IF(H21="",1E6,H21)))+ROW()/1E7
... I55: =IF(B55="","",RANK(N55,$N$6:$N$55,1)) | J55: =IF(B55="","",IF(N(D55)<=0,"Paid",IFERROR(INDEX(Engine!$B$10:$B$530,COUNTIF(INDEX(Engine!$T$10:$BQ$530,0,I55),">0.005")+1),"20+ years"))) | K55: =IF(B55="","",IF(N(D55)<=0,0,IF(F55<=D55*E55/1200,"Never",IF(N(E55)=0,ROUNDUP(D55/F55,0),ROUNDUP(NPER(E55/1200,-F55,D55),0))))) | L55: =IF(B55="","",IF(K55="Never","Never",IF(OR(N(E55)=0,N(D55)<=0),0,F55*NPER(E55/1200,-F55,D55)-D55))) | M55: =IF(B55="","",N(D55)*N(E55)/100/365) | N55: =IF(B55="",1E12+ROW(),CHOOSE(Setup!$C$15,IF(AND(N(E55)>0,F55<=D55*E55/1200),-1E9-E55,D55),-E55*1E6+D55/1E6,IF(H55="",1E6,H55)))+ROW()/1E7
B57: Total | D57: =SUM(D6:D55) | F57: =SUM(F6:F55) | M57: =SUM(M6:M55)
B58: "Never" means paying only the minimum never clears that balance. If the debt also charges interest, it grows, and the PaidInYellow order puts it first.

Sheet Yearly Bills
B1: Yearly bills
B2: Bills you know are coming, just not every month. A little per payday means they stop being surprises.
B5: Bill | C5: Cost per year | D5: Month it's due | E5: Set aside per payday | F5: Saved so far
B6: Car repairs | C6: 600 | D6: Any time | E6: =IF(N(C6)=0,"",C6/Setup!$C$13)
B7: Gifts and holidays | C7: 500 | D7: December | E7: =IF(N(C7)=0,"",C7/Setup!$C$13)
E8: =IF(N(C8)=0,"",C8/Setup!$C$13)
E9: =IF(N(C9)=0,"",C9/Setup!$C$13)
E10: =IF(N(C10)=0,"",C10/Setup!$C$13)
E11: =IF(N(C11)=0,"",C11/Setup!$C$13)
E12: =IF(N(C12)=0,"",C12/Setup!$C$13)
E13: =IF(N(C13)=0,"",C13/Setup!$C$13)
E14: =IF(N(C14)=0,"",C14/Setup!$C$13)
E15: =IF(N(C15)=0,"",C15/Setup!$C$13)
E16: =IF(N(C16)=0,"",C16/Setup!$C$13)
E17: =IF(N(C17)=0,"",C17/Setup!$C$13)
E18: =IF(N(C18)=0,"",C18/Setup!$C$13)
E19: =IF(N(C19)=0,"",C19/Setup!$C$13)
... E25: =IF(N(C25)=0,"",C25/Setup!$C$13)
B27: Total | C27: =SUM(C6:C25) | E27: =SUM(E6:E25) | F27: =SUM(F6:F25)
B29: Keep this money in the same plain separate account as your buffer, or a second one if that helps you leave it alone.

Sheet Compare
B1: Compare
B2: Your plan next to paying only the minimums.
C5: ="Your plan ("&Setup!$C$11&")" | D5: Minimums only
B6: Debt-free by | C6: =Dashboard!B5 | D6: =IF(COUNTIF(Debts!$K$6:$K$55,"Never")>0,"Never",EDATE(Setup!$C$7,MAX(Debts!$K$6:$K$55)))
B7: Months to go | C7: =IFERROR(ROUND((Engine!$B$2)*12/Setup!$C$13,0),"") | D7: =IF(COUNTIF(Debts!$K$6:$K$55,"Never")>0,"Never",MAX(Debts!$K$6:$K$55))
B8: Total interest | C8: =SUM(Engine!$I$11:$I$530) | D8: =IF(COUNTIF(Debts!$L$6:$L$55,"Never")>0,"Never ends",SUM(Debts!$L$6:$L$55))
B10: Want to compare payoff orders? Change "Payoff order" on Setup and write down what you see.
B12: Payoff order | C12: Debt-free by | D12: Total interest
B13: PaidInYellow order
B14: Biggest interest first
B15: My own order
B17: If the gap is small, pick the order you'll stick with. Clearing a small debt early keeps many people going.
B19: Your payoff order
B20: Debt | C20: Balance today | D20: Paid off by | E20: Order
B21: =Engine!T$4 | C21: =IF(B21="","",Engine!T$5) | D21: =IF(B21="","",IF(Engine!T$5<=0,"Paid",IFERROR(INDEX(Engine!$B$10:$B$530,COUNTIF(Engine!T$10:T$530,">0.005")+1),"20+ years"))) | E21: =IF(B21="","",1)
B22: =Engine!U$4 | C22: =IF(B22="","",Engine!U$5) | D22: =IF(B22="","",IF(Engine!U$5<=0,"Paid",IFERROR(INDEX(Engine!$B$10:$B$530,COUNTIF(Engine!U$10:U$530,">0.005")+1),"20+ years"))) | E22: =IF(B22="","",2)
B23: =Engine!V$4 | C23: =IF(B23="","",Engine!V$5) | D23: =IF(B23="","",IF(Engine!V$5<=0,"Paid",IFERROR(INDEX(Engine!$B$10:$B$530,COUNTIF(Engine!V$10:V$530,">0.005")+1),"20+ years"))) | E23: =IF(B23="","",3)
B24: =Engine!W$4 | C24: =IF(B24="","",Engine!W$5) | D24: =IF(B24="","",IF(Engine!W$5<=0,"Paid",IFERROR(INDEX(Engine!$B$10:$B$530,COUNTIF(Engine!W$10:W$530,">0.005")+1),"20+ years"))) | E24: =IF(B24="","",4)
B25: =Engine!X$4 | C25: =IF(B25="","",Engine!X$5) | D25: =IF(B25="","",IF(Engine!X$5<=0,"Paid",IFERROR(INDEX(Engine!$B$10:$B$530,COUNTIF(Engine!X$10:X$530,">0.005")+1),"20+ years"))) | E25: =IF(B25="","",5)
B26: =Engine!Y$4 | C26: =IF(B26="","",Engine!Y$5) | D26: =IF(B26="","",IF(Engine!Y$5<=0,"Paid",IFERROR(INDEX(Engine!$B$10:$B$530,COUNTIF(Engine!Y$10:Y$530,">0.005")+1),"20+ years"))) | E26: =IF(B26="","",6)
B27: =Engine!Z$4 | C27: =IF(B27="","",Engine!Z$5) | D27: =IF(B27="","",IF(Engine!Z$5<=0,"Paid",IFERROR(INDEX(Engine!$B$10:$B$530,COUNTIF(Engine!Z$10:Z$530,">0.005")+1),"20+ years"))) | E27: =IF(B27="","",7)
B28: =Engine!AA$4 | C28: =IF(B28="","",Engine!AA$5) | D28: =IF(B28="","",IF(Engine!AA$5<=0,"Paid",IFERROR(INDEX(Engine!$B$10:$B$530,COUNTIF(Engine!AA$10:AA$530,">0.005")+1),"20+ years"))) | E28: =IF(B28="","",8)
B29: =Engine!AB$4 | C29: =IF(B29="","",Engine!AB$5) | D29: =IF(B29="","",IF(Engine!AB$5<=0,"Paid",IFERROR(INDEX(Engine!$B$10:$B$530,COUNTIF(Engine!AB$10:AB$530,">0.005")+1),"20+ years"))) | E29: =IF(B29="","",9)
B30: =Engine!AC$4 | C30: =IF(B30="","",Engine!AC$5) | D30: =IF(B30="","",IF(Engine!AC$5<=0,"Paid",IFERROR(INDEX(Engine!$B$10:$B$530,COUNTIF(Engine!AC$10:AC$530,">0.005")+1),"20+ years"))) | E30: =IF(B30="","",10)
B31: =Engine!AD$4 | C31: =IF(B31="","",Engine!AD$5) | D31: =IF(B31="","",IF(Engine!AD$5<=0,"Paid",IFERROR(INDEX(Engine!$B$10:$B$530,COUNTIF(Engine!AD$10:AD$530,">0.005")+1),"20+ years"))) | E31: =IF(B31="","",11)
B32: =Engine!AE$4 | C32: =IF(B32="","",Engine!AE$5) | D32: =IF(B32="","",IF(Engine!AE$5<=0,"Paid",IFERROR(INDEX(Engine!$B$10:$B$530,COUNTIF(Engine!AE$10:AE$530,">0.005")+1),"20+ years"))) | E32: =IF(B32="","",12)
B33: =Engine!AF$4 | C33: =IF(B33="","",Engine!AF$5) | D33: =IF(B33="","",IF(Engine!AF$5<=0,"Paid",IFERROR(INDEX(Engine!$B$10:$B$530,COUNTIF(Engine!AF$10:AF$530,">0.005")+1),"20+ years"))) | E33: =IF(B33="","",13)
B34: =Engine!AG$4 | C34: =IF(B34="","",Engine!AG$5) | D34: =IF(B34="","",IF(Engine!AG$5<=0,"Paid",IFERROR(INDEX(Engine!$B$10:$B$530,COUNTIF(Engine!AG$10:AG$530,">0.005")+1),"20+ years"))) | E34: =IF(B34="","",14)
B35: =Engine!AH$4 | C35: =IF(B35="","",Engine!AH$5) | D35: =IF(B35="","",IF(Engine!AH$5<=0,"Paid",IFERROR(INDEX(Engine!$B$10:$B$530,COUNTIF(Engine!AH$10:AH$530,">0.005")+1),"20+ years"))) | E35: =IF(B35="","",15)
B36: =Engine!AI$4 | C36: =IF(B36="","",Engine!AI$5) | D36: =IF(B36="","",IF(Engine!AI$5<=0,"Paid",IFERROR(INDEX(Engine!$B$10:$B$530,COUNTIF(Engine!AI$10:AI$530,">0.005")+1),"20+ years"))) | E36: =IF(B36="","",16)
B37: =Engine!AJ$4 | C37: =IF(B37="","",Engine!AJ$5) | D37: =IF(B37="","",IF(Engine!AJ$5<=0,"Paid",IFERROR(INDEX(Engine!$B$10:$B$530,COUNTIF(Engine!AJ$10:AJ$530,">0.005")+1),"20+ years"))) | E37: =IF(B37="","",17)
B38: =Engine!AK$4 | C38: =IF(B38="","",Engine!AK$5) | D38: =IF(B38="","",IF(Engine!AK$5<=0,"Paid",IFERROR(INDEX(Engine!$B$10:$B$530,COUNTIF(Engine!AK$10:AK$530,">0.005")+1),"20+ years"))) | E38: =IF(B38="","",18)
B39: =Engine!AL$4 | C39: =IF(B39="","",Engine!AL$5) | D39: =IF(B39="","",IF(Engine!AL$5<=0,"Paid",IFERROR(INDEX(Engine!$B$10:$B$530,COUNTIF(Engine!AL$10:AL$530,">0.005")+1),"20+ years"))) | E39: =IF(B39="","",19)
B40: =Engine!AM$4 | C40: =IF(B40="","",Engine!AM$5) | D40: =IF(B40="","",IF(Engine!AM$5<=0,"Paid",IFERROR(INDEX(Engine!$B$10:$B$530,COUNTIF(Engine!AM$10:AM$530,">0.005")+1),"20+ years"))) | E40: =IF(B40="","",20)
B41: =Engine!AN$4 | C41: =IF(B41="","",Engine!AN$5) | D41: =IF(B41="","",IF(Engine!AN$5<=0,"Paid",IFERROR(INDEX(Engine!$B$10:$B$530,COUNTIF(Engine!AN$10:AN$530,">0.005")+1),"20+ years"))) | E41: =IF(B41="","",21)
B42: =Engine!AO$4 | C42: =IF(B42="","",Engine!AO$5) | D42: =IF(B42="","",IF(Engine!AO$5<=0,"Paid",IFERROR(INDEX(Engine!$B$10:$B$530,COUNTIF(Engine!AO$10:AO$530,">0.005")+1),"20+ years"))) | E42: =IF(B42="","",22)
B43: =Engine!AP$4 | C43: =IF(B43="","",Engine!AP$5) | D43: =IF(B43="","",IF(Engine!AP$5<=0,"Paid",IFERROR(INDEX(Engine!$B$10:$B$530,COUNTIF(Engine!AP$10:AP$530,">0.005")+1),"20+ years"))) | E43: =IF(B43="","",23)
B44: =Engine!AQ$4 | C44: =IF(B44="","",Engine!AQ$5) | D44: =IF(B44="","",IF(Engine!AQ$5<=0,"Paid",IFERROR(INDEX(Engine!$B$10:$B$530,COUNTIF(Engine!AQ$10:AQ$530,">0.005")+1),"20+ years"))) | E44: =IF(B44="","",24)
B45: =Engine!AR$4 | C45: =IF(B45="","",Engine!AR$5) | D45: =IF(B45="","",IF(Engine!AR$5<=0,"Paid",IFERROR(INDEX(Engine!$B$10:$B$530,COUNTIF(Engine!AR$10:AR$530,">0.005")+1),"20+ years"))) | E45: =IF(B45="","",25)
B46: =Engine!AS$4 | C46: =IF(B46="","",Engine!AS$5) | D46: =IF(B46="","",IF(Engine!AS$5<=0,"Paid",IFERROR(INDEX(Engine!$B$10:$B$530,COUNTIF(Engine!AS$10:AS$530,">0.005")+1),"20+ years"))) | E46: =IF(B46="","",26)
...

Sheet Engine
A1: Paid paydays | B1: =COUNTIF('Paycheck Plan'!$C$7:$C$526,"Paid") | C1: Next index | D1: =B1+1
A2: Debt-free row | B2: =COUNTIF($J$10:$J$530,">0.005")
S3: debts row | T3: =MATCH(SMALL(Debts!$N$6:$N$55,1),Debts!$N$6:$N$55,0) | U3: =MATCH(SMALL(Debts!$N$6:$N$55,2),Debts!$N$6:$N$55,0) | V3: =MATCH(SMALL(Debts!$N$6:$N$55,3),Debts!$N$6:$N$55,0) | W3: =MATCH(SMALL(Debts!$N$6:$N$55,4),Debts!$N$6:$N$55,0) | X3: =MATCH(SMALL(Debts!$N$6:$N$55,5),Debts!$N$6:$N$55,0) | Y3: =MATCH(SMALL(Debts!$N$6:$N$55,6),Debts!$N$6:$N$55,0) | Z3: =MATCH(SMALL(Debts!$N$6:$N$55,7),Debts!$N$6:$N$55,0) | AA3: =MATCH(SMALL(Debts!$N$6:$N$55,8),Debts!$N$6:$N$55,0) | AB3: =MATCH(SMALL(Debts!$N$6:$N$55,9),Debts!$N$6:$N$55,0) | AC3: =MATCH(SMALL(Debts!$N$6:$N$55,10),Debts!$N$6:$N$55,0) | AD3: =MATCH(SMALL(Debts!$N$6:$N$55,11),Debts!$N$6:$N$55,0) | AE3: =MATCH(SMALL(Debts!$N$6:$N$55,12),Debts!$N$6:$N$55,0) | AF3: =MATCH(SMALL(Debts!$N$6:$N$55,13),Debts!$N$6:$N$55,0) | AG3: =MATCH(SMALL(Debts!$N$6:$N$55,14),Debts!$N$6:$N$55,0) | AH3: =MATCH(SMALL(Debts!$N$6:$N$55,15),Debts!$N$6:$N$55,0) | AI3: =MATCH(SMALL(Debts!$N$6:$N$55,16),Debts!$N$6:$N$55,0) | AJ3: =MATCH(SMALL(Debts!$N$6:$N$55,17),Debts!$N$6:$N$55,0) | AK3: =MATCH(SMALL(Debts!$N$6:$N$55,18),Debts!$N$6:$N$55,0) | AL3: =MATCH(SMALL(Debts!$N$6:$N$55,19),Debts!$N$6:$N$55,0) | AM3: =MATCH(SMALL(Debts!$N$6:$N$55,20),Debts!$N$6:$N$55,0) | AN3: =MATCH(SMALL(Debts!$N$6:$N$55,21),Debts!$N$6:$N$55,0) | AO3: =MATCH(SMALL(Debts!$N$6:$N$55,22),Debts!$N$6:$N$55,0) | AP3: =MATCH(SMALL(Debts!$N$6:$N$55,23),Debts!$N$6:$N$55,0) | AQ3: =MATCH(SMALL(Debts!$N$6:$N$55,24),Debts!$N$6:$N$55,0) | AR3: =MATCH(SMALL(Debts!$N$6:$N$55,25),Debts!$N$6:$N$55,0) | AS3: =MATCH(SMALL(Debts!$N$6:$N$55,26),Debts!$N$6:$N$55,0) | AT3: =MATCH(SMALL(Debts!$N$6:$N$55,27),Debts!$N$6:$N$55,0) | AU3: =MATCH(SMALL(Debts!$N$6:$N$55,28),Debts!$N$6:$N$55,0) | AV3: =MATCH(SMALL(Debts!$N$6:$N$55,29),Debts!$N$6:$N$55,0) | AW3: =MATCH(SMALL(Debts!$N$6:$N$55,30),Debts!$N$6:$N$55,0) | AX3: =MATCH(SMALL(Debts!$N$6:$N$55,31),Debts!$N$6:$N$55,0) | AY3: =MATCH(SMALL(Debts!$N$6:$N$55,32),Debts!$N$6:$N$55,0) | AZ3: =MATCH(SMALL(Debts!$N$6:$N$55,33),Debts!$N$6:$N$55,0) | BA3: =MATCH(SMALL(Debts!$N$6:$N$55,34),Debts!$N$6:$N$55,0) | BB3: =MATCH(SMALL(Debts!$N$6:$N$55,35),Debts!$N$6:$N$55,0) | BC3: =MATCH(SMALL(Debts!$N$6:$N$55,36),Debts!$N$6:$N$55,0) | BD3: =MATCH(SMALL(Debts!$N$6:$N$55,37),Debts!$N$6:$N$55,0) | BE3: =MATCH(SMALL(Debts!$N$6:$N$55,38),Debts!$N$6:$N$55,0) | BF3: =MATCH(SMALL(Debts!$N$6:$N$55,39),Debts!$N$6:$N$55,0) | BG3: =MATCH(SMALL(Debts!$N$6:$N$55,40),Debts!$N$6:$N$55,0) | BH3: =MATCH(SMALL(Debts!$N$6:$N$55,41),Debts!$N$6:$N$55,0) | BI3: =MATCH(SMALL(Debts!$N$6:$N$55,42),Debts!$N$6:$N$55,0) | BJ3: =MATCH(SMALL(Debts!$N$6:$N$55,43),Debts!$N$6:$N$55,0) | BK3: =MATCH(SMALL(Debts!$N$6:$N$55,44),Debts!$N$6:$N$55,0) | BL3: =MATCH(SMALL(Debts!$N$6:$N$55,45),Debts!$N$6:$N$55,0) | BM3: =MATCH(SMALL(Debts!$N$6:$N$55,46),Debts!$N$6:$N$55,0) | BN3: =MATCH(SMALL(Debts!$N$6:$N$55,47),Debts!$N$6:$N$55,0) | BO3: =MATCH(SMALL(Debts!$N$6:$N$55,48),Debts!$N$6:$N$55,0) | BP3: =MATCH(SMALL(Debts!$N$6:$N$55,49),Debts!$N$6:$N$55,0) | BQ3: =MATCH(SMALL(Debts!$N$6:$N$55,50),Debts!$N$6:$N$55,0)
S4: name | T4: =IF(INDEX(Debts!$B$6:$B$55,T3)="","",INDEX(Debts!$B$6:$B$55,T3)&"") | U4: =IF(INDEX(Debts!$B$6:$B$55,U3)="","",INDEX(Debts!$B$6:$B$55,U3)&"") | V4: =IF(INDEX(Debts!$B$6:$B$55,V3)="","",INDEX(Debts!$B$6:$B$55,V3)&"") | W4: =IF(INDEX(Debts!$B$6:$B$55,W3)="","",INDEX(Debts!$B$6:$B$55,W3)&"") | X4: =IF(INDEX(Debts!$B$6:$B$55,X3)="","",INDEX(Debts!$B$6:$B$55,X3)&"") | Y4: =IF(INDEX(Debts!$B$6:$B$55,Y3)="","",INDEX(Debts!$B$6:$B$55,Y3)&"") | Z4: =IF(INDEX(Debts!$B$6:$B$55,Z3)="","",INDEX(Debts!$B$6:$B$55,Z3)&"") | AA4: =IF(INDEX(Debts!$B$6:$B$55,AA3)="","",INDEX(Debts!$B$6:$B$55,AA3)&"") | ... BQ4: =IF(INDEX(Debts!$B$6:$B$55,BQ3)="","",INDEX(Debts!$B$6:$B$55,BQ3)&"")
S5: start balance | T5: =N(INDEX(Debts!$D$6:$D$55,T3)) | U5: =N(INDEX(Debts!$D$6:$D$55,U3)) | V5: =N(INDEX(Debts!$D$6:$D$55,V3)) | W5: =N(INDEX(Debts!$D$6:$D$55,W3)) | X5: =N(INDEX(Debts!$D$6:$D$55,X3)) | Y5: =N(INDEX(Debts!$D$6:$D$55,Y3)) | Z5: =N(INDEX(Debts!$D$6:$D$55,Z3)) | AA5: =N(INDEX(Debts!$D$6:$D$55,AA3)) | ... BQ5: =N(INDEX(Debts!$D$6:$D$55,BQ3))
S6: rate (decimal) | T6: =N(INDEX(Debts!$E$6:$E$55,T3))/100 | U6: =N(INDEX(Debts!$E$6:$E$55,U3))/100 | V6: =N(INDEX(Debts!$E$6:$E$55,V3))/100 | W6: =N(INDEX(Debts!$E$6:$E$55,W3))/100 | X6: =N(INDEX(Debts!$E$6:$E$55,X3))/100 | Y6: =N(INDEX(Debts!$E$6:$E$55,Y3))/100 | Z6: =N(INDEX(Debts!$E$6:$E$55,Z3))/100 | AA6: =N(INDEX(Debts!$E$6:$E$55,AA3))/100 | ... BQ6: =N(INDEX(Debts!$E$6:$E$55,BQ3))/100
S7: minimum per payday | T7: =N(INDEX(Debts!$F$6:$F$55,T3))*12/Setup!$C$13 | U7: =N(INDEX(Debts!$F$6:$F$55,U3))*12/Setup!$C$13 | V7: =N(INDEX(Debts!$F$6:$F$55,V3))*12/Setup!$C$13 | W7: =N(INDEX(Debts!$F$6:$F$55,W3))*12/Setup!$C$13 | X7: =N(INDEX(Debts!$F$6:$F$55,X3))*12/Setup!$C$13 | Y7: =N(INDEX(Debts!$F$6:$F$55,Y3))*12/Setup!$C$13 | Z7: =N(INDEX(Debts!$F$6:$F$55,Z3))*12/Setup!$C$13 | AA7: =N(INDEX(Debts!$F$6:$F$55,AA3))*12/Setup!$C$13 | ... BQ7: =N(INDEX(Debts!$F$6:$F$55,BQ3))*12/Setup!$C$13
A9: n | B9: date | C9: adj | D9: charges | E9: to buffer | F9: buffer | G9: yearly | H9: pot | I9: interest | J9: total | K9: focus rank | M9: chart idx | N9: chart date | O9: chart debt left | T9: balances by rank | BR9: minimum paid | DP9: extra paid
A10: 0 | B10: =Setup!$C$7-ROUND(365/Setup!$C$13,0) | F10: =Setup!$C$9 | J10: =SUM(T10:BQ10) | T10: =T5 | U10: =U5 | V10: =V5 | W10: =W5 | X10: =X5 | Y10: =Y5 | Z10: =Z5 | AA10: =AA5 | ... BQ10: =BQ5
A11: =A10+1 | B11: =IF(Setup!$C$6="Every week",Setup!$C$7+7*(A11-1),IF(Setup!$C$6="Every 2 weeks",Setup!$C$7+14*(A11-1),IF(Setup!$C$6="Every month",EDATE(Setup!$C$7,A11-1),EOMONTH(Setup!$C$7,INT((A11-1+Setup!$C$20)/2)-1)+MIN(IF(MOD(A11-1+Setup!$C$20,2)=0,Setup!$C$18,Setup!$C$19),DAY(EOMONTH(Setup!$C$7,INT((A11-1+Setup!$C$20)/2))))))) | C11: =N('Paycheck Plan'!J7) | D11: =N('Paycheck Plan'!K7) | E11: =MIN(MAX(0,Setup!$C$10-F10),MAX(0,Setup!$C$8+C11-G11)) | F11: =F10+E11 | G11: =MIN(Setup!$C$14,MAX(0,Setup!$C$8+C11)) | H11: =MAX(0,Setup!$C$8+C11-G11-E11)+SUM($T$7:$BQ$7)-SUM(BR11:DO11) | I11: =SUMPRODUCT(T10:BQ10,$T$6:$BQ$6)/Setup!$C$13 | J11: =SUM(T11:BQ11) | K11: =IF(MAX(DP11:FM11)>0,MATCH(MAX(DP11:FM11),DP11:FM11,0),1) | M11: =ROUND(0*$B$2/39,0)+1 | N11: =INDEX($B$10:$B$530,MIN(M11,521)) | O11: =INDEX($J$10:$J$530,MIN(M11,521)) | T11: =MAX(0,T10*(1+T$6/Setup!$C$13)-BR11-DP11)+IF($K11=1,$D11,0) | U11: =MAX(0,U10*(1+U$6/Setup!$C$13)-BS11-DQ11)+IF($K11=2,$D11,0) | V11: =MAX(0,V10*(1+V$6/Setup!$C$13)-BT11-DR11)+IF($K11=3,$D11,0) | W11: =MAX(0,W10*(1+W$6/Setup!$C$13)-BU11-DS11)+IF($K11=4,$D11,0) | X11: =MAX(0,X10*(1+X$6/Setup!$C$13)-BV11-DT11)+IF($K11=5,$D11,0) | Y11: =MAX(0,Y10*(1+Y$6/Setup!$C$13)-BW11-DU11)+IF($K11=6,$D11,0) | Z11: =MAX(0,Z10*(1+Z$6/Setup!$C$13)-BX11-DV11)+IF($K11=7,$D11,0) | AA11: =MAX(0,AA10*(1+AA$6/Setup!$C$13)-BY11-DW11)+IF($K11=8,$D11,0) | AB11: =MAX(0,AB10*(1+AB$6/Setup!$C$13)-BZ11-DX11)+IF($K11=9,$D11,0) | AC11: =MAX(0,AC10*(1+AC$6/Setup!$C$13)-CA11-DY11)+IF($K11=10,$D11,0) | AD11: =MAX(0,AD10*(1+AD$6/Setup!$C$13)-CB11-DZ11)+IF($K11=11,$D11,0) | AE11: =MAX(0,AE10*(1+AE$6/Setup!$C$13)-CC11-EA11)+IF($K11=12,$D11,0) | AF11: =MAX(0,AF10*(1+AF$6/Setup!$C$13)-CD11-EB11)+IF($K11=13,$D11,0) | AG11: =MAX(0,AG10*(1+AG$6/Setup!$C$13)-CE11-EC11)+IF($K11=14,$D11,0) | AH11: =MAX(0,AH10*(1+AH$6/Setup!$C$13)-CF11-ED11)+IF($K11=15,$D11,0) | AI11: =MAX(0,AI10*(1+AI$6/Setup!$C$13)-CG11-EE11)+IF($K11=16,$D11,0) | AJ11: =MAX(0,AJ10*(1+AJ$6/Setup!$C$13)-CH11-EF11)+IF($K11=17,$D11,0) | AK11: =MAX(0,AK10*(1+AK$6/Setup!$C$13)-CI11-EG11)+IF($K11=18,$D11,0) | AL11: =MAX(0,AL10*(1+AL$6/Setup!$C$13)-CJ11-EH11)+IF($K11=19,$D11,0) | AM11: =MAX(0,AM10*(1+AM$6/Setup!$C$13)-CK11-EI11)+IF($K11=20,$D11,0) | AN11: =MAX(0,AN10*(1+AN$6/Setup!$C$13)-CL11-EJ11)+IF($K11=21,$D11,0) | AO11: =MAX(0,AO10*(1+AO$6/Setup!$C$13)-CM11-EK11)+IF($K11=22,$D11,0) | AP11: =MAX(0,AP10*(1+AP$6/Setup!$C$13)-CN11-EL11)+IF($K11=23,$D11,0) | AQ11: =MAX(0,AQ10*(1+AQ$6/Setup!$C$13)-CO11-EM11)+IF($K11=24,$D11,0) | AR11: =MAX(0,AR10*(1+AR$6/Setup!$C$13)-CP11-EN11)+IF($K11=25,$D11,0) | AS11: =MAX(0,AS10*(1+AS$6/Setup!$C$13)-CQ11-EO11)+IF($K11=26,$D11,0) | AT11: =MAX(0,AT10*(1+AT$6/Setup!$C$13)-CR11-EP11)+IF($K11=27,$D11,0) | AU11: =MAX(0,AU10*(1+AU$6/Setup!$C$13)-CS11-EQ11)+IF($K11=28,$D11,0) | AV11: =MAX(0,AV10*(1+AV$6/Setup!$C$13)-CT11-ER11)+IF($K11=29,$D11,0) | AW11: =MAX(0,AW10*(1+AW$6/Setup!$C$13)-CU11-ES11)+IF($K11=30,$D11,0) | AX11: =MAX(0,AX10*(1+AX$6/Setup!$C$13)-CV11-ET11)+IF($K11=31,$D11,0) | AY11: =MAX(0,AY10*(1+AY$6/Setup!$C$13)-CW11-EU11)+IF($K11=32,$D11,0) | AZ11: =MAX(0,AZ10*(1+AZ$6/Setup!$C$13)-CX11-EV11)+IF($K11=33,$D11,0) | BA11: =MAX(0,BA10*(1+BA$6/Setup!$C$13)-CY11-EW11)+IF($K11=34,$D11,0) | BB11: =MAX(0,BB10*(1+BB$6/Setup!$C$13)-CZ11-EX11)+IF($K11=35,$D11,0) | BC11: =MAX(0,BC10*(1+BC$6/Setup!$C$13)-DA11-EY11)+IF($K11=36,$D11,0) | BD11: =MAX(0,BD10*(1+BD$6/Setup!$C$13)-DB11-EZ11)+IF($K11=37,$D11,0) | BE11: =MAX(0,BE10*(1+BE$6/Setup!$C$13)-DC11-FA11)+IF($K11=38,$D11,0) | BF11: =MAX(0,BF10*(1+BF$6/Setup!$C$13)-DD11-FB11)+IF($K11=39,$D11,0) | BG11: =MAX(0,BG10*(1+BG$6/Setup!$C$13)-DE11-FC11)+IF($K11=40,$D11,0) | BH11: =MAX(0,BH10*(1+BH$6/Setup!$C$13)-DF11-FD11)+IF($K11=41,$D11,0) | BI11: =MAX(0,BI10*(1+BI$6/Setup!$C$13)-DG11-FE11)+IF($K11=42,$D11,0) | BJ11: =MAX(0,BJ10*(1+BJ$6/Setup!$C$13)-DH11-FF11)+IF($K11=43,$D11,0) | BK11: =MAX(0,BK10*(1+BK$6/Setup!$C$13)-DI11-FG11)+IF($K11=44,$D11,0) | BL11: =MAX(0,BL10*(1+BL$6/Setup!$C$13)-DJ11-FH11)+IF($K11=45,$D11,0) | BM11: =MAX(0,BM10*(1+BM$6/Setup!$C$13)-DK11-FI11)+IF($K11=46,$D11,0) | BN11: =MAX(0,BN10*(1+BN$6/Setup!$C$13)-DL11-FJ11)+IF($K11=47,$D11,0) | BO11: =MAX(0,BO10*(1+BO$6/Setup!$C$13)-DM11-FK11)+IF($K11=48,$D11,0) | BP11: =MAX(0,BP10*(1+BP$6/Setup!$C$13)-DN11-FL11)+IF($K11=49,$D11,0) | BQ11: =MAX(0,BQ10*(1+BQ$6/Setup!$C$13)-DO11-FM11)+IF($K11=50,$D11,0) | BR11: =MIN(T10*(1+T$6/Setup!$C$13),T$7) | BS11: =MIN(U10*(1+U$6/Setup!$C$13),U$7) | BT11: =MIN(V10*(1+V$6/Setup!$C$13),V$7) | BU11: =MIN(W10*(1+W$6/Setup!$C$13),W$7) | BV11: =MIN(X10*(1+X$6/Setup!$C$13),X$7) | BW11: =MIN(Y10*(1+Y$6/Setup!$C$13),Y$7) | BX11: =MIN(Z10*(1+Z$6/Setup!$C$13),Z$7) | BY11: =MIN(AA10*(1+AA$6/Setup!$C$13),AA$7) | ... DO11: =MIN(BQ10*(1+BQ$6/Setup!$C$13),BQ$7) | DP11: =MIN(T10*(1+T$6/Setup!$C$13)-BR11,$H11) | DQ11: =MIN(U10*(1+U$6/Setup!$C$13)-BS11,MAX(0,$H11-SUM($DP11:DP11))) | DR11: =MIN(V10*(1+V$6/Setup!$C$13)-BT11,MAX(0,$H11-SUM($DP11:DQ11))) | DS11: =MIN(W10*(1+W$6/Setup!$C$13)-BU11,MAX(0,$H11-SUM($DP11:DR11))) | DT11: =MIN(X10*(1+X$6/Setup!$C$13)-BV11,MAX(0,$H11-SUM($DP11:DS11))) | DU11: =MIN(Y10*(1+Y$6/Setup!$C$13)-BW11,MAX(0,$H11-SUM($DP11:DT11))) | DV11: =MIN(Z10*(1+Z$6/Setup!$C$13)-BX11,MAX(0,$H11-SUM($DP11:DU11))) | DW11: =MIN(AA10*(1+AA$6/Setup!$C$13)-BY11,MAX(0,$H11-SUM($DP11:DV11))) | DX11: =MIN(AB10*(1+AB$6/Setup!$C$13)-BZ11,MAX(0,$H11-SUM($DP11:DW11))) | ... FM11: =MIN(BQ10*(1+BQ$6/Setup!$C$13)-DO11,MAX(0,$H11-SUM($DP11:FL11)))
